{"datetime": "2025-07-30 09:10:13 941925 PM", "level": "INFO", "func_name": "main", "lineno": 51, "filename": "understanding_tasks.py", "msg": "Main function calling"}
{"datetime": "2025-07-30 09:10:13 941925 PM", "level": "INFO", "func_name": "task_factory", "lineno": 413, "filename": "tasks.py", "msg": {"msg": "initalizing task", "vars": {"loop": "<ProactorEventLoop running=True closed=False debug=True>", "coro": "<coroutine object another at 0x0000022D131358A0>", "task_name": "ASYNC-Custom-task-Task-1"}}}
{"datetime": "2025-07-30 09:10:13 941925 PM", "level": "INFO", "func_name": "__init__", "lineno": 48, "filename": "tasks.py", "msg": {"msg": "__init__ initalized"}}
{"datetime": "2025-07-30 09:10:13 941925 PM", "level": "INFO", "func_name": "__init__", "lineno": 76, "filename": "tasks.py", "msg": {"msg": "self.__step scheduled on EVENT_LOOP in __init__", "vars": {"task_name": "ASYNC-Custom-task-Task-1", "scheduler_type": "call_soon"}}}
{"datetime": "2025-07-30 09:10:13 957776 PM", "level": "INFO", "func_name": "__init__", "lineno": 79, "filename": "tasks.py", "msg": {"msg": "__init__ after scheduling __step on EVENT_LOOP using loop.call_soon", "vars": {"task_name": "ASYNC-Custom-task-Task-1", "scheduler_type": "call_soon"}}}
{"datetime": "2025-07-30 09:10:13 961402 PM", "level": "INFO", "func_name": "__step", "lineno": 233, "filename": "tasks.py", "msg": {"msg": "Entered self.__step", "method_signature": "__step(self, exc = None)", "vars": {"task_name": "ASYNC-Custom-task-Task-1", "exc": "None", "sent_from": "'__init__'"}}}
{"datetime": "2025-07-30 09:10:13 961402 PM", "level": "INFO", "func_name": "__step", "lineno": 243, "filename": "tasks.py", "msg": {"msg": "will initalized self._fut_waiter value", "vars": {"task_name": "ASYNC-Custom-task-Task-1"}}}
{"datetime": "2025-07-30 09:10:13 961402 PM", "level": "INFO", "func_name": "__step", "lineno": 245, "filename": "tasks.py", "msg": {"msg": "initalized self._fut_waiter to None", "vars": {"task_name": "ASYNC-Custom-task-Task-1"}}}
{"datetime": "2025-07-30 09:10:13 961402 PM", "level": "INFO", "func_name": "__step", "lineno": 250, "filename": "tasks.py", "msg": {"msg": "`try` of try-finally in `self.__step`. Call to __step_run_and_handle_request in next line.", "vars": {"task_name": "ASYNC-Custom-task-Task-1"}}}
{"datetime": "2025-07-30 09:10:13 961402 PM", "level": "INFO", "func_name": "__step_run_and_handle_result", "lineno": 264, "filename": "tasks.py", "msg": {"msg": "__step_run_and_handle_request entered", "method_signature": "__step_run_and_handle_result(self, exc)", "vars": {"task_name": "ASYNC-Custom-task-Task-1", "exc": "None"}}}
{"datetime": "2025-07-30 09:10:13 961402 PM", "level": "INFO", "func_name": "__step_run_and_handle_result", "lineno": 271, "filename": "tasks.py", "msg": {"msg": "`__step_run_and_hanle_result` main try-except exc is None so `coro.send()` in next line.", "vars": {"task_name": "ASYNC-Custom-task-Task-1"}}}
{"datetime": "2025-07-30 09:10:13 961402 PM", "level": "INFO", "func_name": "another", "lineno": 17, "filename": "understanding_tasks.py", "msg": "=========== ANOTHER Will fetch resul============="}
{"datetime": "2025-07-30 09:10:13 961402 PM", "level": "INFO", "func_name": "rresult", "lineno": 11, "filename": "understanding_tasks.py", "msg": {"msg": "rresult will sleep .1 second and return 9"}}
{"datetime": "2025-07-30 09:10:13 961402 PM", "level": "INFO", "func_name": "__step_run_and_handle_result", "lineno": 274, "filename": "tasks.py", "msg": {"msg:": "__step_run_and_handle_result main try-except after `coro.send()`", "vars": {"task_name": "ASYNC-Custom-task-Task-1"}}}
{"datetime": "2025-07-30 09:10:13 973437 PM", "level": "INFO", "func_name": "__step_run_and_handle_result", "lineno": 312, "filename": "tasks.py", "msg": {"msg": "try-else in __step_run_and_handle_result", "vars": {"task_name": "ASYNC-Custom-task-Task-1", "future_name": "ASYNC-Custom-task-Task-1: name: 1", "result": "<Future pending created at C:\\Users\\shaik\\AppData\\Local\\Programs\\Python\\Python312\\Lib\\asyncio\\base_events.py:448>", "is_asyncio_future_blocking": "getattr(result,\"_asyncio_future_blocking\", None)= True"}}}
{"datetime": "2025-07-30 09:10:13 973437 PM", "level": "INFO", "func_name": "__step_run_and_handle_result", "lineno": 315, "filename": "tasks.py", "msg": {"msg": "is_future blocking", "vars": {"task_name": "ASYNC-Custom-task-Task-1", "future_name": "ASYNC-Custom-task-Task-1: name: 1", "is_future_blocking": true}}}
{"datetime": "2025-07-30 09:10:13 973437 PM", "level": "INFO", "func_name": "__step_run_and_handle_result", "lineno": 332, "filename": "tasks.py", "msg": {"msg": "scheduling on EVENT_LOOP callback to fututre.add_done_call_back", "vars": {"task_name": "ASYNC-Custom-task-Task-1", "future_name": "ASYNC-Custom-task-Task-1: name: 1", "future_state": "PENDING", "result": "<Future pending created at C:\\Users\\shaik\\AppData\\Local\\Programs\\Python\\Python312\\Lib\\asyncio\\base_events.py:448>", "scheduler_type": "call_soon"}}}
{"datetime": "2025-07-30 09:10:13 973437 PM", "level": "INFO", "func_name": "__step_run_and_handle_result", "lineno": 337, "filename": "tasks.py", "msg": {"msg": "After scheduling callbacks to fut. self._future_wait = result", "vars": {"task_name": "ASYNC-Custom-task-Task-1", "future_name": "ASYNC-Custom-task-Task-1: name: 1", "result": "<Future pending cb=[Task.__wakeup()] created at C:\\Users\\shaik\\AppData\\Local\\Programs\\Python\\Python312\\Lib\\asyncio\\base_events.py:448>", "self._fut_waiter": null, "future_state": "PENDING", "future_callbacks_list(fut._callbacks)": [["__wakeup", "method"]]}}}
{"datetime": "2025-07-30 09:10:13 973437 PM", "level": "INFO", "func_name": "__step_run_and_handle_result", "lineno": 343, "filename": "tasks.py", "msg": {"msg": "self._fut_waiter set to result", "vars": {"task_name": "ASYNC-Custom-task-Task-1", "future_name": "ASYNC-Custom-task-Task-1: name: 1", "future_state": "PENDING", "self._fut_waiter": "<Future pending cb=[Task.__wakeup()] created at C:\\Users\\shaik\\AppData\\Local\\Programs\\Python\\Python312\\Lib\\asyncio\\base_events.py:448>"}}}
{"datetime": "2025-07-30 09:10:13 973437 PM", "level": "INFO", "func_name": "__step_run_and_handle_result", "lineno": 376, "filename": "tasks.py", "msg": {"msg": "self finally set to None", "vars": {"task_name": "ASYNC-Custom-task-Task-1"}}}
{"datetime": "2025-07-30 09:10:13 973437 PM", "level": "INFO", "func_name": "__step", "lineno": 252, "filename": "tasks.py", "msg": {"msg": "`try` of try-finally in `self.__step`. After __step_run_and_handle_result", "vars": {"task_name": "ASYNC-Custom-task-Task-1"}}}
{"datetime": "2025-07-30 09:10:13 973437 PM", "level": "INFO", "func_name": "__step", "lineno": 257, "filename": "tasks.py", "msg": {"msg": "`finally` of try-finally in `self.__step`. Call to _leave_task next and then set self to None", "vars": {"task_name": "ASYNC-Custom-task-Task-1"}}}
{"datetime": "2025-07-30 09:10:13 973437 PM", "level": "INFO", "func_name": "__step", "lineno": 261, "filename": "tasks.py", "msg": {"msg": "`finally` of try-finally in `self.__step`.ASYNC-Custom-task-Task-1 set to none", "vars": {"task_name": "ASYNC-Custom-task-Task-1"}}}
{"datetime": "2025-07-30 09:10:14 069771 PM", "level": "INFO", "func_name": "__wakeup", "lineno": 381, "filename": "tasks.py", "msg": {"msg": "__wakeup entered", "vars": {"task_name": "ASYNC-Custom-task-Task-1", "future_name": "ASYNC-Custom-task-Task-1: name: 1", "future_state": "FINISHED"}}}
{"datetime": "2025-07-30 09:10:14 071798 PM", "level": "INFO", "func_name": "__wakeup", "lineno": 384, "filename": "tasks.py", "msg": {"msg": "will call future.result()", "vars": {"task_name": "ASYNC-Custom-task-Task-1", "future_name": "ASYNC-Custom-task-Task-1: name: 1"}}}
{"datetime": "2025-07-30 09:10:14 071798 PM", "level": "INFO", "func_name": "__wakeup", "lineno": 386, "filename": "tasks.py", "msg": {"msg": "__wakeup after future.result()", "vars": {"task_name": "ASYNC-Custom-task-Task-1", "future_name": "ASYNC-Custom-task-Task-1: name: 1", "future._state": "FINISHED"}}}
{"datetime": "2025-07-30 09:10:14 071798 PM", "level": "INFO", "func_name": "__wakeup", "lineno": 402, "filename": "tasks.py", "msg": {"msg": "__wakeup faced no exception when it called future.result()(ASYNC-Custom-task-Task-1: name: 1). calling again __step with no exc. I guess StopIteration will be raised", "vars": {"task_name": "ASYNC-Custom-task-Task-1", "future_name": "ASYNC-Custom-task-Task-1: name: 1", "future._result": null}}}
{"datetime": "2025-07-30 09:10:14 071798 PM", "level": "INFO", "func_name": "__step", "lineno": 233, "filename": "tasks.py", "msg": {"msg": "Entered self.__step", "method_signature": "__step(self, exc = None)", "vars": {"task_name": "ASYNC-Custom-task-Task-1", "exc": "None", "sent_from": "'_wakeup._else'"}}}
{"datetime": "2025-07-30 09:10:14 071798 PM", "level": "INFO", "func_name": "__step", "lineno": 243, "filename": "tasks.py", "msg": {"msg": "will initalized self._fut_waiter value", "vars": {"task_name": "ASYNC-Custom-task-Task-1"}}}
{"datetime": "2025-07-30 09:10:14 071798 PM", "level": "INFO", "func_name": "__step", "lineno": 245, "filename": "tasks.py", "msg": {"msg": "initalized self._fut_waiter to None", "vars": {"task_name": "ASYNC-Custom-task-Task-1"}}}
{"datetime": "2025-07-30 09:10:14 071798 PM", "level": "INFO", "func_name": "__step", "lineno": 250, "filename": "tasks.py", "msg": {"msg": "`try` of try-finally in `self.__step`. Call to __step_run_and_handle_request in next line.", "vars": {"task_name": "ASYNC-Custom-task-Task-1"}}}
{"datetime": "2025-07-30 09:10:14 071798 PM", "level": "INFO", "func_name": "__step_run_and_handle_result", "lineno": 264, "filename": "tasks.py", "msg": {"msg": "__step_run_and_handle_request entered", "method_signature": "__step_run_and_handle_result(self, exc)", "vars": {"task_name": "ASYNC-Custom-task-Task-1", "exc": "None"}}}
{"datetime": "2025-07-30 09:10:14 081445 PM", "level": "INFO", "func_name": "__step_run_and_handle_result", "lineno": 271, "filename": "tasks.py", "msg": {"msg": "`__step_run_and_hanle_result` main try-except exc is None so `coro.send()` in next line.", "vars": {"task_name": "ASYNC-Custom-task-Task-1"}}}
{"datetime": "2025-07-30 09:10:14 081445 PM", "level": "INFO", "func_name": "rresult", "lineno": 13, "filename": "understanding_tasks.py", "msg": {"msg": "sending 9 as result."}}
{"datetime": "2025-07-30 09:10:14 081445 PM", "level": "INFO", "func_name": "another", "lineno": 19, "filename": "understanding_tasks.py", "msg": {"msg": "================ GOT RESULT 9"}}
{"datetime": "2025-07-30 09:10:14 081445 PM", "level": "INFO", "func_name": "__step_run_and_handle_result", "lineno": 284, "filename": "tasks.py", "msg": {"msg": "StopIteration exception encountered.", "vars": {"task_name": "ASYNC-Custom-task-Task-1", "future_name": "NO_AWAITABLE"}}}
{"datetime": "2025-07-30 09:10:14 081445 PM", "level": "INFO", "func_name": "__step_run_and_handle_result", "lineno": 293, "filename": "tasks.py", "msg": {"msg": "__step_run_and_handle_result StopIteration encountered but the task is not cancelled.", "vars": {"task_name": "ASYNC-Custom-task-Task-1", "exc.value": "None"}}}
{"datetime": "2025-07-30 09:10:14 086766 PM", "level": "INFO", "func_name": "__step_run_and_handle_result", "lineno": 296, "filename": "tasks.py", "msg": {"msg": "super().set_result(exc.value)", "vars": {"task_name": "ASYNC-Custom-task-Task-1"}}}
{"datetime": "2025-07-30 09:10:14 086766 PM", "level": "INFO", "func_name": "__step_run_and_handle_result", "lineno": 376, "filename": "tasks.py", "msg": {"msg": "self finally set to None", "vars": {"task_name": "ASYNC-Custom-task-Task-1"}}}
{"datetime": "2025-07-30 09:10:14 086766 PM", "level": "INFO", "func_name": "__step", "lineno": 252, "filename": "tasks.py", "msg": {"msg": "`try` of try-finally in `self.__step`. After __step_run_and_handle_result", "vars": {"task_name": "ASYNC-Custom-task-Task-1"}}}
{"datetime": "2025-07-30 09:10:14 086766 PM", "level": "INFO", "func_name": "__step", "lineno": 257, "filename": "tasks.py", "msg": {"msg": "`finally` of try-finally in `self.__step`. Call to _leave_task next and then set self to None", "vars": {"task_name": "ASYNC-Custom-task-Task-1"}}}
{"datetime": "2025-07-30 09:10:14 086766 PM", "level": "INFO", "func_name": "__step", "lineno": 261, "filename": "tasks.py", "msg": {"msg": "`finally` of try-finally in `self.__step`.ASYNC-Custom-task-Task-1 set to none", "vars": {"task_name": "ASYNC-Custom-task-Task-1"}}}
{"datetime": "2025-07-30 09:10:14 086766 PM", "level": "INFO", "func_name": "__wakeup", "lineno": 406, "filename": "tasks.py", "msg": {"msg": "end of __wakeup. set self = None", "vars": {"task_name": "ASYNC-Custom-task-Task-1", "future_name": "ASYNC-Custom-task-Task-1: name: 1"}}}
{"datetime": "2025-07-30 09:10:14 086766 PM", "level": "INFO", "func_name": "task_factory", "lineno": 413, "filename": "tasks.py", "msg": {"msg": "initalizing task", "vars": {"loop": "<ProactorEventLoop running=False closed=False debug=True>", "coro": "<coroutine object BaseEventLoop.shutdown_asyncgens at 0x0000022D1315CAE0>", "task_name": "ASYNC-Custom-task-Task-2"}}}
{"datetime": "2025-07-30 09:10:14 086766 PM", "level": "INFO", "func_name": "__init__", "lineno": 48, "filename": "tasks.py", "msg": {"msg": "__init__ initalized"}}
{"datetime": "2025-07-30 09:10:14 086766 PM", "level": "INFO", "func_name": "__init__", "lineno": 76, "filename": "tasks.py", "msg": {"msg": "self.__step scheduled on EVENT_LOOP in __init__", "vars": {"task_name": "ASYNC-Custom-task-Task-2", "scheduler_type": "call_soon"}}}
{"datetime": "2025-07-30 09:10:14 086766 PM", "level": "INFO", "func_name": "__init__", "lineno": 79, "filename": "tasks.py", "msg": {"msg": "__init__ after scheduling __step on EVENT_LOOP using loop.call_soon", "vars": {"task_name": "ASYNC-Custom-task-Task-2", "scheduler_type": "call_soon"}}}
{"datetime": "2025-07-30 09:10:14 086766 PM", "level": "INFO", "func_name": "__step", "lineno": 233, "filename": "tasks.py", "msg": {"msg": "Entered self.__step", "method_signature": "__step(self, exc = None)", "vars": {"task_name": "ASYNC-Custom-task-Task-2", "exc": "None", "sent_from": "'__init__'"}}}
{"datetime": "2025-07-30 09:10:14 093823 PM", "level": "INFO", "func_name": "__step", "lineno": 243, "filename": "tasks.py", "msg": {"msg": "will initalized self._fut_waiter value", "vars": {"task_name": "ASYNC-Custom-task-Task-2"}}}
{"datetime": "2025-07-30 09:10:14 093823 PM", "level": "INFO", "func_name": "__step", "lineno": 245, "filename": "tasks.py", "msg": {"msg": "initalized self._fut_waiter to None", "vars": {"task_name": "ASYNC-Custom-task-Task-2"}}}
{"datetime": "2025-07-30 09:10:14 093823 PM", "level": "INFO", "func_name": "__step", "lineno": 250, "filename": "tasks.py", "msg": {"msg": "`try` of try-finally in `self.__step`. Call to __step_run_and_handle_request in next line.", "vars": {"task_name": "ASYNC-Custom-task-Task-2"}}}
{"datetime": "2025-07-30 09:10:14 093823 PM", "level": "INFO", "func_name": "__step_run_and_handle_result", "lineno": 264, "filename": "tasks.py", "msg": {"msg": "__step_run_and_handle_request entered", "method_signature": "__step_run_and_handle_result(self, exc)", "vars": {"task_name": "ASYNC-Custom-task-Task-2", "exc": "None"}}}
{"datetime": "2025-07-30 09:10:14 093823 PM", "level": "INFO", "func_name": "__step_run_and_handle_result", "lineno": 271, "filename": "tasks.py", "msg": {"msg": "`__step_run_and_hanle_result` main try-except exc is None so `coro.send()` in next line.", "vars": {"task_name": "ASYNC-Custom-task-Task-2"}}}
{"datetime": "2025-07-30 09:10:14 093823 PM", "level": "INFO", "func_name": "__step_run_and_handle_result", "lineno": 284, "filename": "tasks.py", "msg": {"msg": "StopIteration exception encountered.", "vars": {"task_name": "ASYNC-Custom-task-Task-2", "future_name": "NO_AWAITABLE"}}}
{"datetime": "2025-07-30 09:10:14 093823 PM", "level": "INFO", "func_name": "__step_run_and_handle_result", "lineno": 293, "filename": "tasks.py", "msg": {"msg": "__step_run_and_handle_result StopIteration encountered but the task is not cancelled.", "vars": {"task_name": "ASYNC-Custom-task-Task-2", "exc.value": "None"}}}
{"datetime": "2025-07-30 09:10:14 093823 PM", "level": "INFO", "func_name": "__step_run_and_handle_result", "lineno": 296, "filename": "tasks.py", "msg": {"msg": "super().set_result(exc.value)", "vars": {"task_name": "ASYNC-Custom-task-Task-2"}}}
{"datetime": "2025-07-30 09:10:14 093823 PM", "level": "INFO", "func_name": "__step_run_and_handle_result", "lineno": 376, "filename": "tasks.py", "msg": {"msg": "self finally set to None", "vars": {"task_name": "ASYNC-Custom-task-Task-2"}}}
{"datetime": "2025-07-30 09:10:14 093823 PM", "level": "INFO", "func_name": "__step", "lineno": 252, "filename": "tasks.py", "msg": {"msg": "`try` of try-finally in `self.__step`. After __step_run_and_handle_result", "vars": {"task_name": "ASYNC-Custom-task-Task-2"}}}
{"datetime": "2025-07-30 09:10:14 093823 PM", "level": "INFO", "func_name": "__step", "lineno": 257, "filename": "tasks.py", "msg": {"msg": "`finally` of try-finally in `self.__step`. Call to _leave_task next and then set self to None", "vars": {"task_name": "ASYNC-Custom-task-Task-2"}}}
{"datetime": "2025-07-30 09:10:14 093823 PM", "level": "INFO", "func_name": "__step", "lineno": 261, "filename": "tasks.py", "msg": {"msg": "`finally` of try-finally in `self.__step`.ASYNC-Custom-task-Task-2 set to none", "vars": {"task_name": "ASYNC-Custom-task-Task-2"}}}
{"datetime": "2025-07-30 09:10:14 093823 PM", "level": "INFO", "func_name": "task_factory", "lineno": 413, "filename": "tasks.py", "msg": {"msg": "initalizing task", "vars": {"loop": "<ProactorEventLoop running=False closed=False debug=True>", "coro": "<coroutine object BaseEventLoop.shutdown_default_executor at 0x0000022D13109F30>", "task_name": "ASYNC-Custom-task-Task-3"}}}
{"datetime": "2025-07-30 09:10:14 101395 PM", "level": "INFO", "func_name": "__init__", "lineno": 48, "filename": "tasks.py", "msg": {"msg": "__init__ initalized"}}
{"datetime": "2025-07-30 09:10:14 101944 PM", "level": "INFO", "func_name": "__init__", "lineno": 76, "filename": "tasks.py", "msg": {"msg": "self.__step scheduled on EVENT_LOOP in __init__", "vars": {"task_name": "ASYNC-Custom-task-Task-3", "scheduler_type": "call_soon"}}}
{"datetime": "2025-07-30 09:10:14 101944 PM", "level": "INFO", "func_name": "__init__", "lineno": 79, "filename": "tasks.py", "msg": {"msg": "__init__ after scheduling __step on EVENT_LOOP using loop.call_soon", "vars": {"task_name": "ASYNC-Custom-task-Task-3", "scheduler_type": "call_soon"}}}
{"datetime": "2025-07-30 09:10:14 101944 PM", "level": "INFO", "func_name": "__step", "lineno": 233, "filename": "tasks.py", "msg": {"msg": "Entered self.__step", "method_signature": "__step(self, exc = None)", "vars": {"task_name": "ASYNC-Custom-task-Task-3", "exc": "None", "sent_from": "'__init__'"}}}
{"datetime": "2025-07-30 09:10:14 101944 PM", "level": "INFO", "func_name": "__step", "lineno": 243, "filename": "tasks.py", "msg": {"msg": "will initalized self._fut_waiter value", "vars": {"task_name": "ASYNC-Custom-task-Task-3"}}}
{"datetime": "2025-07-30 09:10:14 101944 PM", "level": "INFO", "func_name": "__step", "lineno": 245, "filename": "tasks.py", "msg": {"msg": "initalized self._fut_waiter to None", "vars": {"task_name": "ASYNC-Custom-task-Task-3"}}}
{"datetime": "2025-07-30 09:10:14 101944 PM", "level": "INFO", "func_name": "__step", "lineno": 250, "filename": "tasks.py", "msg": {"msg": "`try` of try-finally in `self.__step`. Call to __step_run_and_handle_request in next line.", "vars": {"task_name": "ASYNC-Custom-task-Task-3"}}}
{"datetime": "2025-07-30 09:10:14 101944 PM", "level": "INFO", "func_name": "__step_run_and_handle_result", "lineno": 264, "filename": "tasks.py", "msg": {"msg": "__step_run_and_handle_request entered", "method_signature": "__step_run_and_handle_result(self, exc)", "vars": {"task_name": "ASYNC-Custom-task-Task-3", "exc": "None"}}}
{"datetime": "2025-07-30 09:10:14 101944 PM", "level": "INFO", "func_name": "__step_run_and_handle_result", "lineno": 271, "filename": "tasks.py", "msg": {"msg": "`__step_run_and_hanle_result` main try-except exc is None so `coro.send()` in next line.", "vars": {"task_name": "ASYNC-Custom-task-Task-3"}}}
{"datetime": "2025-07-30 09:10:14 101944 PM", "level": "INFO", "func_name": "__step_run_and_handle_result", "lineno": 284, "filename": "tasks.py", "msg": {"msg": "StopIteration exception encountered.", "vars": {"task_name": "ASYNC-Custom-task-Task-3", "future_name": "NO_AWAITABLE"}}}
{"datetime": "2025-07-30 09:10:14 101944 PM", "level": "INFO", "func_name": "__step_run_and_handle_result", "lineno": 293, "filename": "tasks.py", "msg": {"msg": "__step_run_and_handle_result StopIteration encountered but the task is not cancelled.", "vars": {"task_name": "ASYNC-Custom-task-Task-3", "exc.value": "None"}}}
{"datetime": "2025-07-30 09:10:14 101944 PM", "level": "INFO", "func_name": "__step_run_and_handle_result", "lineno": 296, "filename": "tasks.py", "msg": {"msg": "super().set_result(exc.value)", "vars": {"task_name": "ASYNC-Custom-task-Task-3"}}}
{"datetime": "2025-07-30 09:10:14 101944 PM", "level": "INFO", "func_name": "__step_run_and_handle_result", "lineno": 376, "filename": "tasks.py", "msg": {"msg": "self finally set to None", "vars": {"task_name": "ASYNC-Custom-task-Task-3"}}}
{"datetime": "2025-07-30 09:10:14 101944 PM", "level": "INFO", "func_name": "__step", "lineno": 252, "filename": "tasks.py", "msg": {"msg": "`try` of try-finally in `self.__step`. After __step_run_and_handle_result", "vars": {"task_name": "ASYNC-Custom-task-Task-3"}}}
{"datetime": "2025-07-30 09:10:14 101944 PM", "level": "INFO", "func_name": "__step", "lineno": 257, "filename": "tasks.py", "msg": {"msg": "`finally` of try-finally in `self.__step`. Call to _leave_task next and then set self to None", "vars": {"task_name": "ASYNC-Custom-task-Task-3"}}}
{"datetime": "2025-07-30 09:10:14 101944 PM", "level": "INFO", "func_name": "__step", "lineno": 261, "filename": "tasks.py", "msg": {"msg": "`finally` of try-finally in `self.__step`.ASYNC-Custom-task-Task-3 set to none", "vars": {"task_name": "ASYNC-Custom-task-Task-3"}}}
