{"datetime": "2025-07-30 06:46:08 462554 PM", "level": "INFO", "func_name": "main", "lineno": 40, "filename": "understanding_tasks.py", "msg": "Main function calling"}
{"datetime": "2025-07-30 06:46:08 463891 PM", "level": "INFO", "func_name": "task_factory", "lineno": 407, "filename": "tasks.py", "msg": {"msg": "initalizing task", "vars": {"loop": "<ProactorEventLoop running=True closed=False debug=True>", "coro": "<coroutine object first at 0x000001e3f8e2c280>", "task_name": null}}}
{"datetime": "2025-07-30 06:46:08 464859 PM", "level": "INFO", "func_name": "__init__", "lineno": 48, "filename": "tasks.py", "msg": {"msg": "__init__ initalized"}}
{"datetime": "2025-07-30 06:46:08 464859 PM", "level": "INFO", "func_name": "__init__", "lineno": 76, "filename": "tasks.py", "msg": {"msg": "self.__step scheduled on EVENT_LOOP in __init__", "vars": {"task_name": "Custom-task-Task-1"}}}
{"datetime": "2025-07-30 06:46:08 479195 PM", "level": "INFO", "func_name": "__init__", "lineno": 78, "filename": "tasks.py", "msg": {"msg": "__init__ after scheduling __step on EVENT_LOOP using loop.call_soon", "vars": {"task_name": "Custom-task-Task-1"}}}
{"datetime": "2025-07-30 06:46:08 480081 PM", "level": "INFO", "func_name": "task_factory", "lineno": 407, "filename": "tasks.py", "msg": {"msg": "initalizing task", "vars": {"loop": "<ProactorEventLoop running=True closed=False debug=True>", "coro": "<coroutine object second at 0x000001e3f8e2c340>", "task_name": null}}}
{"datetime": "2025-07-30 06:46:08 480081 PM", "level": "INFO", "func_name": "__init__", "lineno": 48, "filename": "tasks.py", "msg": {"msg": "__init__ initalized"}}
{"datetime": "2025-07-30 06:46:08 481176 PM", "level": "INFO", "func_name": "__init__", "lineno": 76, "filename": "tasks.py", "msg": {"msg": "self.__step scheduled on EVENT_LOOP in __init__", "vars": {"task_name": "Custom-task-Task-2"}}}
{"datetime": "2025-07-30 06:46:08 482181 PM", "level": "INFO", "func_name": "__init__", "lineno": 78, "filename": "tasks.py", "msg": {"msg": "__init__ after scheduling __step on EVENT_LOOP using loop.call_soon", "vars": {"task_name": "Custom-task-Task-2"}}}
{"datetime": "2025-07-30 06:46:08 485277 PM", "level": "INFO", "func_name": "__step", "lineno": 231, "filename": "tasks.py", "msg": {"msg": "Entered self.__step", "method_signature": "__step(self, exc = None)", "vars": {"task_name": "Custom-task-Task-1", "exc": "None", "sent_from": "'__init__'"}}}
{"datetime": "2025-07-30 06:46:08 486562 PM", "level": "INFO", "func_name": "__step", "lineno": 241, "filename": "tasks.py", "msg": {"msg": "will initalized self._fut_waiter value", "vars": {"task_name": "Custom-task-Task-1"}}}
{"datetime": "2025-07-30 06:46:08 486882 PM", "level": "INFO", "func_name": "__step", "lineno": 243, "filename": "tasks.py", "msg": {"msg": "initalized self._fut_waiter to None", "vars": {"task_name": "Custom-task-Task-1"}}}
{"datetime": "2025-07-30 06:46:08 486882 PM", "level": "INFO", "func_name": "__step", "lineno": 248, "filename": "tasks.py", "msg": {"msg": "`try` of try-finally in `self.__step`. Call to __step_run_and_handle_request in next line.", "vars": {"task_name": "Custom-task-Task-1"}}}
{"datetime": "2025-07-30 06:46:08 486882 PM", "level": "INFO", "func_name": "__step_run_and_handle_result", "lineno": 262, "filename": "tasks.py", "msg": {"msg": "__step_run_and_handle_request entered", "method_signature": "__step_run_and_handle_result(self, exc)", "vars": {"task_name": "Custom-task-Task-1", "exc": "None"}}}
{"datetime": "2025-07-30 06:46:08 487888 PM", "level": "INFO", "func_name": "__step_run_and_handle_result", "lineno": 269, "filename": "tasks.py", "msg": {"msg": "`__step_run_and_hanle_result` main try-except exc is None so `coro.send()` in next line.", "vars": {"task_name": "Custom-task-Task-1"}}}
{"datetime": "2025-07-30 06:46:08 487888 PM", "level": "INFO", "func_name": "first", "lineno": 11, "filename": "understanding_tasks.py", "msg": "======== FIRST.FIRST ==================="}
{"datetime": "2025-07-30 06:46:08 490980 PM", "level": "INFO", "func_name": "__step_run_and_handle_result", "lineno": 272, "filename": "tasks.py", "msg": {"msg:": "__step_run_and_handle_result main try-except after `coro.send()`", "vars": {"task_name": "Custom-task-Task-1"}}}
{"datetime": "2025-07-30 06:46:08 490980 PM", "level": "INFO", "func_name": "__step_run_and_handle_result", "lineno": 310, "filename": "tasks.py", "msg": {"msg": "try-else in __step_run_and_handle_result", "vars": {"task_name": "Custom-task-Task-1", "future_name": "Custom-task-Task-1: name: 1", "result": "<Future pending created at C:\\msys64\\mingw64\\lib\\python3.12\\asyncio\\base_events.py:448>", "is_asyncio_future_blocking": "getattr(result,\"_asyncio_future_blocking\", None)= True"}}}
{"datetime": "2025-07-30 06:46:08 491995 PM", "level": "INFO", "func_name": "__step_run_and_handle_result", "lineno": 313, "filename": "tasks.py", "msg": {"msg": "is_future blocking", "vars": {"task_name": "Custom-task-Task-1", "future_name": "Custom-task-Task-1: name: 1", "is_future_blocking": true}}}
{"datetime": "2025-07-30 06:46:08 491995 PM", "level": "INFO", "func_name": "__step_run_and_handle_result", "lineno": 330, "filename": "tasks.py", "msg": {"msg": "scheduling on EVENT_LOOP callback to fututre.add_done_call_back", "vars": {"task_name": "Custom-task-Task-1", "future_name": "Custom-task-Task-1: name: 1", "future_state": "PENDING", "result": "<Future pending created at C:\\msys64\\mingw64\\lib\\python3.12\\asyncio\\base_events.py:448>"}}}
{"datetime": "2025-07-30 06:46:08 492891 PM", "level": "INFO", "func_name": "__step_run_and_handle_result", "lineno": 335, "filename": "tasks.py", "msg": {"msg": "After scheduling callbacks to fut. self._future_wait = result", "vars": {"task_name": "Custom-task-Task-1", "future_name": "Custom-task-Task-1: name: 1", "result": "<Future pending cb=[Task.__wakeup()] created at C:\\msys64\\mingw64\\lib\\python3.12\\asyncio\\base_events.py:448>", "self._fut_waiter": null, "future_state": "PENDING", "future_callbacks_list(fut._callbacks)": "[(<bound method Task.__wakeup of <Task pending name='Custom-task-Task-1' coro=<first() running at c:/Users/shaik/learning/concurrency/python_concurrency/understanding_tasks.py:12> cb=[gather.<locals>._done_callback() at C:\\msys64\\mingw64\\lib\\python3.12\\asyncio\\tasks.py:767] created at c:\\Users\\shaik\\learning\\concurrency\\python_concurrency\\experiments\\tasks.py:410>>, <_contextvars.Context object at 0x000001e3f8e55bc0>)]"}}}
{"datetime": "2025-07-30 06:46:08 493411 PM", "level": "INFO", "func_name": "__step_run_and_handle_result", "lineno": 340, "filename": "tasks.py", "msg": {"msg": "self._fut_waiter set to result", "vars": {"task_name": "Custom-task-Task-1", "future_name": "Custom-task-Task-1: name: 1", "future_state": "PENDING", "self._fut_waiter": "<Future pending cb=[Task.__wakeup()] created at C:\\msys64\\mingw64\\lib\\python3.12\\asyncio\\base_events.py:448>"}}}
{"datetime": "2025-07-30 06:46:08 493411 PM", "level": "INFO", "func_name": "__step_run_and_handle_result", "lineno": 372, "filename": "tasks.py", "msg": {"msg": "self finally set to None", "vars": {"task_name": "Custom-task-Task-1"}}}
{"datetime": "2025-07-30 06:46:08 493411 PM", "level": "INFO", "func_name": "__step", "lineno": 250, "filename": "tasks.py", "msg": {"msg": "`try` of try-finally in `self.__step`. After __step_run_and_handle_result", "vars": {"task_name": "Custom-task-Task-1"}}}
{"datetime": "2025-07-30 06:46:08 494614 PM", "level": "INFO", "func_name": "__step", "lineno": 255, "filename": "tasks.py", "msg": {"msg": "`finally` of try-finally in `self.__step`. Call to _leave_task next and then set self to None", "vars": {"task_name": "Custom-task-Task-1"}}}
{"datetime": "2025-07-30 06:46:08 494975 PM", "level": "INFO", "func_name": "__step", "lineno": 259, "filename": "tasks.py", "msg": {"msg": "`finally` of try-finally in `self.__step`.Custom-task-Task-1 set to none", "vars": {"task_name": "Custom-task-Task-1"}}}
{"datetime": "2025-07-30 06:46:08 494975 PM", "level": "INFO", "func_name": "__step", "lineno": 231, "filename": "tasks.py", "msg": {"msg": "Entered self.__step", "method_signature": "__step(self, exc = None)", "vars": {"task_name": "Custom-task-Task-2", "exc": "None", "sent_from": "'__init__'"}}}
{"datetime": "2025-07-30 06:46:08 496014 PM", "level": "INFO", "func_name": "__step", "lineno": 241, "filename": "tasks.py", "msg": {"msg": "will initalized self._fut_waiter value", "vars": {"task_name": "Custom-task-Task-2"}}}
{"datetime": "2025-07-30 06:46:08 496014 PM", "level": "INFO", "func_name": "__step", "lineno": 243, "filename": "tasks.py", "msg": {"msg": "initalized self._fut_waiter to None", "vars": {"task_name": "Custom-task-Task-2"}}}
{"datetime": "2025-07-30 06:46:08 496014 PM", "level": "INFO", "func_name": "__step", "lineno": 248, "filename": "tasks.py", "msg": {"msg": "`try` of try-finally in `self.__step`. Call to __step_run_and_handle_request in next line.", "vars": {"task_name": "Custom-task-Task-2"}}}
{"datetime": "2025-07-30 06:46:08 497000 PM", "level": "INFO", "func_name": "__step_run_and_handle_result", "lineno": 262, "filename": "tasks.py", "msg": {"msg": "__step_run_and_handle_request entered", "method_signature": "__step_run_and_handle_result(self, exc)", "vars": {"task_name": "Custom-task-Task-2", "exc": "None"}}}
{"datetime": "2025-07-30 06:46:08 497312 PM", "level": "INFO", "func_name": "__step_run_and_handle_result", "lineno": 269, "filename": "tasks.py", "msg": {"msg": "`__step_run_and_hanle_result` main try-except exc is None so `coro.send()` in next line.", "vars": {"task_name": "Custom-task-Task-2"}}}
{"datetime": "2025-07-30 06:46:08 497312 PM", "level": "INFO", "func_name": "second", "lineno": 20, "filename": "understanding_tasks.py", "msg": "======== SECOND.FIRST ==================="}
{"datetime": "2025-07-30 06:46:08 498484 PM", "level": "INFO", "func_name": "__step_run_and_handle_result", "lineno": 272, "filename": "tasks.py", "msg": {"msg:": "__step_run_and_handle_result main try-except after `coro.send()`", "vars": {"task_name": "Custom-task-Task-2"}}}
{"datetime": "2025-07-30 06:46:08 499490 PM", "level": "INFO", "func_name": "__step_run_and_handle_result", "lineno": 310, "filename": "tasks.py", "msg": {"msg": "try-else in __step_run_and_handle_result", "vars": {"task_name": "Custom-task-Task-2", "future_name": "Custom-task-Task-2: name: 1", "result": "<Future pending created at C:\\msys64\\mingw64\\lib\\python3.12\\asyncio\\base_events.py:448>", "is_asyncio_future_blocking": "getattr(result,\"_asyncio_future_blocking\", None)= True"}}}
{"datetime": "2025-07-30 06:46:08 499490 PM", "level": "INFO", "func_name": "__step_run_and_handle_result", "lineno": 313, "filename": "tasks.py", "msg": {"msg": "is_future blocking", "vars": {"task_name": "Custom-task-Task-2", "future_name": "Custom-task-Task-2: name: 1", "is_future_blocking": true}}}
{"datetime": "2025-07-30 06:46:08 499490 PM", "level": "INFO", "func_name": "__step_run_and_handle_result", "lineno": 330, "filename": "tasks.py", "msg": {"msg": "scheduling on EVENT_LOOP callback to fututre.add_done_call_back", "vars": {"task_name": "Custom-task-Task-2", "future_name": "Custom-task-Task-2: name: 1", "future_state": "PENDING", "result": "<Future pending created at C:\\msys64\\mingw64\\lib\\python3.12\\asyncio\\base_events.py:448>"}}}
{"datetime": "2025-07-30 06:46:08 499490 PM", "level": "INFO", "func_name": "__step_run_and_handle_result", "lineno": 335, "filename": "tasks.py", "msg": {"msg": "After scheduling callbacks to fut. self._future_wait = result", "vars": {"task_name": "Custom-task-Task-2", "future_name": "Custom-task-Task-2: name: 1", "result": "<Future pending cb=[Task.__wakeup()] created at C:\\msys64\\mingw64\\lib\\python3.12\\asyncio\\base_events.py:448>", "self._fut_waiter": null, "future_state": "PENDING", "future_callbacks_list(fut._callbacks)": "[(<bound method Task.__wakeup of <Task pending name='Custom-task-Task-2' coro=<second() running at c:/Users/shaik/learning/concurrency/python_concurrency/understanding_tasks.py:21> cb=[gather.<locals>._done_callback() at C:\\msys64\\mingw64\\lib\\python3.12\\asyncio\\tasks.py:767] created at c:\\Users\\shaik\\learning\\concurrency\\python_concurrency\\experiments\\tasks.py:410>>, <_contextvars.Context object at 0x000001e3f8e560c0>)]"}}}
{"datetime": "2025-07-30 06:46:08 499490 PM", "level": "INFO", "func_name": "__step_run_and_handle_result", "lineno": 340, "filename": "tasks.py", "msg": {"msg": "self._fut_waiter set to result", "vars": {"task_name": "Custom-task-Task-2", "future_name": "Custom-task-Task-2: name: 1", "future_state": "PENDING", "self._fut_waiter": "<Future pending cb=[Task.__wakeup()] created at C:\\msys64\\mingw64\\lib\\python3.12\\asyncio\\base_events.py:448>"}}}
{"datetime": "2025-07-30 06:46:08 499490 PM", "level": "INFO", "func_name": "__step_run_and_handle_result", "lineno": 372, "filename": "tasks.py", "msg": {"msg": "self finally set to None", "vars": {"task_name": "Custom-task-Task-2"}}}
{"datetime": "2025-07-30 06:46:08 499490 PM", "level": "INFO", "func_name": "__step", "lineno": 250, "filename": "tasks.py", "msg": {"msg": "`try` of try-finally in `self.__step`. After __step_run_and_handle_result", "vars": {"task_name": "Custom-task-Task-2"}}}
{"datetime": "2025-07-30 06:46:08 499490 PM", "level": "INFO", "func_name": "__step", "lineno": 255, "filename": "tasks.py", "msg": {"msg": "`finally` of try-finally in `self.__step`. Call to _leave_task next and then set self to None", "vars": {"task_name": "Custom-task-Task-2"}}}
{"datetime": "2025-07-30 06:46:08 503879 PM", "level": "INFO", "func_name": "__step", "lineno": 259, "filename": "tasks.py", "msg": {"msg": "`finally` of try-finally in `self.__step`.Custom-task-Task-2 set to none", "vars": {"task_name": "Custom-task-Task-2"}}}
{"datetime": "2025-07-30 06:46:08 993298 PM", "level": "INFO", "func_name": "__wakeup", "lineno": 377, "filename": "tasks.py", "msg": {"msg": "__wakeup entered", "vars": {"task_name": "Custom-task-Task-2", "future_name": "Custom-task-Task-2: name: 1", "future_state": "FINISHED"}}}
{"datetime": "2025-07-30 06:46:08 994257 PM", "level": "INFO", "func_name": "__wakeup", "lineno": 380, "filename": "tasks.py", "msg": {"msg": "will call future.result()", "vars": {"task_name": "Custom-task-Task-2", "future_name": "Custom-task-Task-2: name: 1"}}}
{"datetime": "2025-07-30 06:46:08 994257 PM", "level": "INFO", "func_name": "__wakeup", "lineno": 382, "filename": "tasks.py", "msg": {"msg": "__wakeup after future.result()", "vars": {"task_name": "Custom-task-Task-2", "future_name": "Custom-task-Task-2: name: 1", "future._state": "FINISHED"}}}
{"datetime": "2025-07-30 06:46:08 994257 PM", "level": "INFO", "func_name": "__wakeup", "lineno": 398, "filename": "tasks.py", "msg": {"msg": "__wakeup faced no exception when it called future.result()(Custom-task-Task-2: name: 1). calling again __step with no exc. I guess StopIteration will be raised", "vars": {"task_name": "Custom-task-Task-2", "future_name": "Custom-task-Task-2: name: 1"}}}
{"datetime": "2025-07-30 06:46:08 994257 PM", "level": "INFO", "func_name": "__step", "lineno": 231, "filename": "tasks.py", "msg": {"msg": "Entered self.__step", "method_signature": "__step(self, exc = None)", "vars": {"task_name": "Custom-task-Task-2", "exc": "None", "sent_from": "'_wakeup._else'"}}}
{"datetime": "2025-07-30 06:46:08 994257 PM", "level": "INFO", "func_name": "__step", "lineno": 241, "filename": "tasks.py", "msg": {"msg": "will initalized self._fut_waiter value", "vars": {"task_name": "Custom-task-Task-2"}}}
{"datetime": "2025-07-30 06:46:08 994257 PM", "level": "INFO", "func_name": "__step", "lineno": 243, "filename": "tasks.py", "msg": {"msg": "initalized self._fut_waiter to None", "vars": {"task_name": "Custom-task-Task-2"}}}
{"datetime": "2025-07-30 06:46:08 994257 PM", "level": "INFO", "func_name": "__step", "lineno": 248, "filename": "tasks.py", "msg": {"msg": "`try` of try-finally in `self.__step`. Call to __step_run_and_handle_request in next line.", "vars": {"task_name": "Custom-task-Task-2"}}}
{"datetime": "2025-07-30 06:46:08 994257 PM", "level": "INFO", "func_name": "__step_run_and_handle_result", "lineno": 262, "filename": "tasks.py", "msg": {"msg": "__step_run_and_handle_request entered", "method_signature": "__step_run_and_handle_result(self, exc)", "vars": {"task_name": "Custom-task-Task-2", "exc": "None"}}}
{"datetime": "2025-07-30 06:46:08 997917 PM", "level": "INFO", "func_name": "__step_run_and_handle_result", "lineno": 269, "filename": "tasks.py", "msg": {"msg": "`__step_run_and_hanle_result` main try-except exc is None so `coro.send()` in next line.", "vars": {"task_name": "Custom-task-Task-2"}}}
{"datetime": "2025-07-30 06:46:08 997917 PM", "level": "INFO", "func_name": "second", "lineno": 22, "filename": "understanding_tasks.py", "msg": "========= SECOND.SECOND ========================="}
{"datetime": "2025-07-30 06:46:08 997917 PM", "level": "INFO", "func_name": "__step_run_and_handle_result", "lineno": 272, "filename": "tasks.py", "msg": {"msg:": "__step_run_and_handle_result main try-except after `coro.send()`", "vars": {"task_name": "Custom-task-Task-2"}}}
{"datetime": "2025-07-30 06:46:08 999923 PM", "level": "INFO", "func_name": "__step_run_and_handle_result", "lineno": 310, "filename": "tasks.py", "msg": {"msg": "try-else in __step_run_and_handle_result", "vars": {"task_name": "Custom-task-Task-2", "future_name": "Custom-task-Task-2: name: 2", "result": "<Future pending created at C:\\msys64\\mingw64\\lib\\python3.12\\asyncio\\base_events.py:448>", "is_asyncio_future_blocking": "getattr(result,\"_asyncio_future_blocking\", None)= True"}}}
{"datetime": "2025-07-30 06:46:08 999923 PM", "level": "INFO", "func_name": "__step_run_and_handle_result", "lineno": 313, "filename": "tasks.py", "msg": {"msg": "is_future blocking", "vars": {"task_name": "Custom-task-Task-2", "future_name": "Custom-task-Task-2: name: 2", "is_future_blocking": true}}}
{"datetime": "2025-07-30 06:46:08 999923 PM", "level": "INFO", "func_name": "__step_run_and_handle_result", "lineno": 330, "filename": "tasks.py", "msg": {"msg": "scheduling on EVENT_LOOP callback to fututre.add_done_call_back", "vars": {"task_name": "Custom-task-Task-2", "future_name": "Custom-task-Task-2: name: 2", "future_state": "PENDING", "result": "<Future pending created at C:\\msys64\\mingw64\\lib\\python3.12\\asyncio\\base_events.py:448>"}}}
{"datetime": "2025-07-30 06:46:09 001249 PM", "level": "INFO", "func_name": "__step_run_and_handle_result", "lineno": 335, "filename": "tasks.py", "msg": {"msg": "After scheduling callbacks to fut. self._future_wait = result", "vars": {"task_name": "Custom-task-Task-2", "future_name": "Custom-task-Task-2: name: 2", "result": "<Future pending cb=[Task.__wakeup()] created at C:\\msys64\\mingw64\\lib\\python3.12\\asyncio\\base_events.py:448>", "self._fut_waiter": null, "future_state": "PENDING", "future_callbacks_list(fut._callbacks)": "[(<bound method Task.__wakeup of <Task pending name='Custom-task-Task-2' coro=<second() running at c:/Users/shaik/learning/concurrency/python_concurrency/understanding_tasks.py:25> cb=[gather.<locals>._done_callback() at C:\\msys64\\mingw64\\lib\\python3.12\\asyncio\\tasks.py:767] created at c:\\Users\\shaik\\learning\\concurrency\\python_concurrency\\experiments\\tasks.py:410>>, <_contextvars.Context object at 0x000001e3f8e560c0>)]"}}}
{"datetime": "2025-07-30 06:46:09 002256 PM", "level": "INFO", "func_name": "__step_run_and_handle_result", "lineno": 340, "filename": "tasks.py", "msg": {"msg": "self._fut_waiter set to result", "vars": {"task_name": "Custom-task-Task-2", "future_name": "Custom-task-Task-2: name: 2", "future_state": "PENDING", "self._fut_waiter": "<Future pending cb=[Task.__wakeup()] created at C:\\msys64\\mingw64\\lib\\python3.12\\asyncio\\base_events.py:448>"}}}
{"datetime": "2025-07-30 06:46:09 002256 PM", "level": "INFO", "func_name": "__step_run_and_handle_result", "lineno": 372, "filename": "tasks.py", "msg": {"msg": "self finally set to None", "vars": {"task_name": "Custom-task-Task-2"}}}
{"datetime": "2025-07-30 06:46:09 003337 PM", "level": "INFO", "func_name": "__step", "lineno": 250, "filename": "tasks.py", "msg": {"msg": "`try` of try-finally in `self.__step`. After __step_run_and_handle_result", "vars": {"task_name": "Custom-task-Task-2"}}}
{"datetime": "2025-07-30 06:46:09 003757 PM", "level": "INFO", "func_name": "__step", "lineno": 255, "filename": "tasks.py", "msg": {"msg": "`finally` of try-finally in `self.__step`. Call to _leave_task next and then set self to None", "vars": {"task_name": "Custom-task-Task-2"}}}
{"datetime": "2025-07-30 06:46:09 003757 PM", "level": "INFO", "func_name": "__step", "lineno": 259, "filename": "tasks.py", "msg": {"msg": "`finally` of try-finally in `self.__step`.Custom-task-Task-2 set to none", "vars": {"task_name": "Custom-task-Task-2"}}}
{"datetime": "2025-07-30 06:46:09 004401 PM", "level": "INFO", "func_name": "__wakeup", "lineno": 401, "filename": "tasks.py", "msg": {"msg": "end of __wakeup. set self = None", "vars": {"task_name": "Custom-task-Task-2", "future_name": "Custom-task-Task-2: name: 1"}}}
{"datetime": "2025-07-30 06:46:09 093947 PM", "level": "INFO", "func_name": "__wakeup", "lineno": 377, "filename": "tasks.py", "msg": {"msg": "__wakeup entered", "vars": {"task_name": "Custom-task-Task-2", "future_name": "Custom-task-Task-2: name: 2", "future_state": "FINISHED"}}}
{"datetime": "2025-07-30 06:46:09 095036 PM", "level": "INFO", "func_name": "__wakeup", "lineno": 380, "filename": "tasks.py", "msg": {"msg": "will call future.result()", "vars": {"task_name": "Custom-task-Task-2", "future_name": "Custom-task-Task-2: name: 2"}}}
{"datetime": "2025-07-30 06:46:09 095036 PM", "level": "INFO", "func_name": "__wakeup", "lineno": 382, "filename": "tasks.py", "msg": {"msg": "__wakeup after future.result()", "vars": {"task_name": "Custom-task-Task-2", "future_name": "Custom-task-Task-2: name: 2", "future._state": "FINISHED"}}}
{"datetime": "2025-07-30 06:46:09 095949 PM", "level": "INFO", "func_name": "__wakeup", "lineno": 398, "filename": "tasks.py", "msg": {"msg": "__wakeup faced no exception when it called future.result()(Custom-task-Task-2: name: 2). calling again __step with no exc. I guess StopIteration will be raised", "vars": {"task_name": "Custom-task-Task-2", "future_name": "Custom-task-Task-2: name: 2"}}}
{"datetime": "2025-07-30 06:46:09 096392 PM", "level": "INFO", "func_name": "__step", "lineno": 231, "filename": "tasks.py", "msg": {"msg": "Entered self.__step", "method_signature": "__step(self, exc = None)", "vars": {"task_name": "Custom-task-Task-2", "exc": "None", "sent_from": "'_wakeup._else'"}}}
{"datetime": "2025-07-30 06:46:09 096392 PM", "level": "INFO", "func_name": "__step", "lineno": 241, "filename": "tasks.py", "msg": {"msg": "will initalized self._fut_waiter value", "vars": {"task_name": "Custom-task-Task-2"}}}
{"datetime": "2025-07-30 06:46:09 097397 PM", "level": "INFO", "func_name": "__step", "lineno": 243, "filename": "tasks.py", "msg": {"msg": "initalized self._fut_waiter to None", "vars": {"task_name": "Custom-task-Task-2"}}}
{"datetime": "2025-07-30 06:46:09 097397 PM", "level": "INFO", "func_name": "__step", "lineno": 248, "filename": "tasks.py", "msg": {"msg": "`try` of try-finally in `self.__step`. Call to __step_run_and_handle_request in next line.", "vars": {"task_name": "Custom-task-Task-2"}}}
{"datetime": "2025-07-30 06:46:09 097397 PM", "level": "INFO", "func_name": "__step_run_and_handle_result", "lineno": 262, "filename": "tasks.py", "msg": {"msg": "__step_run_and_handle_request entered", "method_signature": "__step_run_and_handle_result(self, exc)", "vars": {"task_name": "Custom-task-Task-2", "exc": "None"}}}
{"datetime": "2025-07-30 06:46:09 098416 PM", "level": "INFO", "func_name": "__step_run_and_handle_result", "lineno": 269, "filename": "tasks.py", "msg": {"msg": "`__step_run_and_hanle_result` main try-except exc is None so `coro.send()` in next line.", "vars": {"task_name": "Custom-task-Task-2"}}}
{"datetime": "2025-07-30 06:46:09 098416 PM", "level": "INFO", "func_name": "second", "lineno": 26, "filename": "understanding_tasks.py", "msg": "========== END ==========="}
{"datetime": "2025-07-30 06:46:09 099400 PM", "level": "INFO", "func_name": "__step_run_and_handle_result", "lineno": 282, "filename": "tasks.py", "msg": {"msg": "StopIteration exception encountered.", "vars": {"task_name": "Custom-task-Task-2", "future_name": "NO_AWAITABLE"}}}
{"datetime": "2025-07-30 06:46:09 099400 PM", "level": "INFO", "func_name": "__step_run_and_handle_result", "lineno": 291, "filename": "tasks.py", "msg": {"msg": "__step_run_and_handle_result StopIteration encountered but the task is not cancelled.", "vars": {"task_name": "Custom-task-Task-2", "exc.value": "None"}}}
{"datetime": "2025-07-30 06:46:09 100332 PM", "level": "INFO", "func_name": "__step_run_and_handle_result", "lineno": 294, "filename": "tasks.py", "msg": {"msg": "super().set_result(exc.value)", "vars": {"task_name": "Custom-task-Task-2"}}}
{"datetime": "2025-07-30 06:46:09 100332 PM", "level": "INFO", "func_name": "__step_run_and_handle_result", "lineno": 372, "filename": "tasks.py", "msg": {"msg": "self finally set to None", "vars": {"task_name": "Custom-task-Task-2"}}}
{"datetime": "2025-07-30 06:46:09 101412 PM", "level": "INFO", "func_name": "__step", "lineno": 250, "filename": "tasks.py", "msg": {"msg": "`try` of try-finally in `self.__step`. After __step_run_and_handle_result", "vars": {"task_name": "Custom-task-Task-2"}}}
{"datetime": "2025-07-30 06:46:09 101412 PM", "level": "INFO", "func_name": "__step", "lineno": 255, "filename": "tasks.py", "msg": {"msg": "`finally` of try-finally in `self.__step`. Call to _leave_task next and then set self to None", "vars": {"task_name": "Custom-task-Task-2"}}}
{"datetime": "2025-07-30 06:46:09 101412 PM", "level": "INFO", "func_name": "__step", "lineno": 259, "filename": "tasks.py", "msg": {"msg": "`finally` of try-finally in `self.__step`.Custom-task-Task-2 set to none", "vars": {"task_name": "Custom-task-Task-2"}}}
{"datetime": "2025-07-30 06:46:09 102412 PM", "level": "INFO", "func_name": "__wakeup", "lineno": 401, "filename": "tasks.py", "msg": {"msg": "end of __wakeup. set self = None", "vars": {"task_name": "Custom-task-Task-2", "future_name": "Custom-task-Task-2: name: 2"}}}
{"datetime": "2025-07-30 06:46:12 494811 PM", "level": "INFO", "func_name": "__wakeup", "lineno": 377, "filename": "tasks.py", "msg": {"msg": "__wakeup entered", "vars": {"task_name": "Custom-task-Task-1", "future_name": "Custom-task-Task-1: name: 1", "future_state": "FINISHED"}}}
{"datetime": "2025-07-30 06:46:12 494811 PM", "level": "INFO", "func_name": "__wakeup", "lineno": 380, "filename": "tasks.py", "msg": {"msg": "will call future.result()", "vars": {"task_name": "Custom-task-Task-1", "future_name": "Custom-task-Task-1: name: 1"}}}
{"datetime": "2025-07-30 06:46:12 494811 PM", "level": "INFO", "func_name": "__wakeup", "lineno": 382, "filename": "tasks.py", "msg": {"msg": "__wakeup after future.result()", "vars": {"task_name": "Custom-task-Task-1", "future_name": "Custom-task-Task-1: name: 1", "future._state": "FINISHED"}}}
{"datetime": "2025-07-30 06:46:12 494811 PM", "level": "INFO", "func_name": "__wakeup", "lineno": 398, "filename": "tasks.py", "msg": {"msg": "__wakeup faced no exception when it called future.result()(Custom-task-Task-1: name: 1). calling again __step with no exc. I guess StopIteration will be raised", "vars": {"task_name": "Custom-task-Task-1", "future_name": "Custom-task-Task-1: name: 1"}}}
{"datetime": "2025-07-30 06:46:12 494811 PM", "level": "INFO", "func_name": "__step", "lineno": 231, "filename": "tasks.py", "msg": {"msg": "Entered self.__step", "method_signature": "__step(self, exc = None)", "vars": {"task_name": "Custom-task-Task-1", "exc": "None", "sent_from": "'_wakeup._else'"}}}
{"datetime": "2025-07-30 06:46:12 494811 PM", "level": "INFO", "func_name": "__step", "lineno": 241, "filename": "tasks.py", "msg": {"msg": "will initalized self._fut_waiter value", "vars": {"task_name": "Custom-task-Task-1"}}}
{"datetime": "2025-07-30 06:46:12 494811 PM", "level": "INFO", "func_name": "__step", "lineno": 243, "filename": "tasks.py", "msg": {"msg": "initalized self._fut_waiter to None", "vars": {"task_name": "Custom-task-Task-1"}}}
{"datetime": "2025-07-30 06:46:12 503502 PM", "level": "INFO", "func_name": "__step", "lineno": 248, "filename": "tasks.py", "msg": {"msg": "`try` of try-finally in `self.__step`. Call to __step_run_and_handle_request in next line.", "vars": {"task_name": "Custom-task-Task-1"}}}
{"datetime": "2025-07-30 06:46:12 504536 PM", "level": "INFO", "func_name": "__step_run_and_handle_result", "lineno": 262, "filename": "tasks.py", "msg": {"msg": "__step_run_and_handle_request entered", "method_signature": "__step_run_and_handle_result(self, exc)", "vars": {"task_name": "Custom-task-Task-1", "exc": "None"}}}
{"datetime": "2025-07-30 06:46:12 505529 PM", "level": "INFO", "func_name": "__step_run_and_handle_result", "lineno": 269, "filename": "tasks.py", "msg": {"msg": "`__step_run_and_hanle_result` main try-except exc is None so `coro.send()` in next line.", "vars": {"task_name": "Custom-task-Task-1"}}}
{"datetime": "2025-07-30 06:46:12 506985 PM", "level": "INFO", "func_name": "first", "lineno": 13, "filename": "understanding_tasks.py", "msg": "========= FIRST.SECOND ========================="}
{"datetime": "2025-07-30 06:46:12 510399 PM", "level": "INFO", "func_name": "__step_run_and_handle_result", "lineno": 272, "filename": "tasks.py", "msg": {"msg:": "__step_run_and_handle_result main try-except after `coro.send()`", "vars": {"task_name": "Custom-task-Task-1"}}}
{"datetime": "2025-07-30 06:46:12 511023 PM", "level": "INFO", "func_name": "__step_run_and_handle_result", "lineno": 310, "filename": "tasks.py", "msg": {"msg": "try-else in __step_run_and_handle_result", "vars": {"task_name": "Custom-task-Task-1", "future_name": "Custom-task-Task-1: name: 2", "result": "<Future pending created at C:\\msys64\\mingw64\\lib\\python3.12\\asyncio\\base_events.py:448>", "is_asyncio_future_blocking": "getattr(result,\"_asyncio_future_blocking\", None)= True"}}}
{"datetime": "2025-07-30 06:46:12 511023 PM", "level": "INFO", "func_name": "__step_run_and_handle_result", "lineno": 313, "filename": "tasks.py", "msg": {"msg": "is_future blocking", "vars": {"task_name": "Custom-task-Task-1", "future_name": "Custom-task-Task-1: name: 2", "is_future_blocking": true}}}
{"datetime": "2025-07-30 06:46:12 512029 PM", "level": "INFO", "func_name": "__step_run_and_handle_result", "lineno": 330, "filename": "tasks.py", "msg": {"msg": "scheduling on EVENT_LOOP callback to fututre.add_done_call_back", "vars": {"task_name": "Custom-task-Task-1", "future_name": "Custom-task-Task-1: name: 2", "future_state": "PENDING", "result": "<Future pending created at C:\\msys64\\mingw64\\lib\\python3.12\\asyncio\\base_events.py:448>"}}}
{"datetime": "2025-07-30 06:46:12 512029 PM", "level": "INFO", "func_name": "__step_run_and_handle_result", "lineno": 335, "filename": "tasks.py", "msg": {"msg": "After scheduling callbacks to fut. self._future_wait = result", "vars": {"task_name": "Custom-task-Task-1", "future_name": "Custom-task-Task-1: name: 2", "result": "<Future pending cb=[Task.__wakeup()] created at C:\\msys64\\mingw64\\lib\\python3.12\\asyncio\\base_events.py:448>", "self._fut_waiter": null, "future_state": "PENDING", "future_callbacks_list(fut._callbacks)": "[(<bound method Task.__wakeup of <Task pending name='Custom-task-Task-1' coro=<first() running at c:/Users/shaik/learning/concurrency/python_concurrency/understanding_tasks.py:16> cb=[gather.<locals>._done_callback() at C:\\msys64\\mingw64\\lib\\python3.12\\asyncio\\tasks.py:767] created at c:\\Users\\shaik\\learning\\concurrency\\python_concurrency\\experiments\\tasks.py:410>>, <_contextvars.Context object at 0x000001e3f8e55bc0>)]"}}}
{"datetime": "2025-07-30 06:46:12 513363 PM", "level": "INFO", "func_name": "__step_run_and_handle_result", "lineno": 340, "filename": "tasks.py", "msg": {"msg": "self._fut_waiter set to result", "vars": {"task_name": "Custom-task-Task-1", "future_name": "Custom-task-Task-1: name: 2", "future_state": "PENDING", "self._fut_waiter": "<Future pending cb=[Task.__wakeup()] created at C:\\msys64\\mingw64\\lib\\python3.12\\asyncio\\base_events.py:448>"}}}
{"datetime": "2025-07-30 06:46:12 513363 PM", "level": "INFO", "func_name": "__step_run_and_handle_result", "lineno": 372, "filename": "tasks.py", "msg": {"msg": "self finally set to None", "vars": {"task_name": "Custom-task-Task-1"}}}
{"datetime": "2025-07-30 06:46:12 514433 PM", "level": "INFO", "func_name": "__step", "lineno": 250, "filename": "tasks.py", "msg": {"msg": "`try` of try-finally in `self.__step`. After __step_run_and_handle_result", "vars": {"task_name": "Custom-task-Task-1"}}}
{"datetime": "2025-07-30 06:46:12 514433 PM", "level": "INFO", "func_name": "__step", "lineno": 255, "filename": "tasks.py", "msg": {"msg": "`finally` of try-finally in `self.__step`. Call to _leave_task next and then set self to None", "vars": {"task_name": "Custom-task-Task-1"}}}
{"datetime": "2025-07-30 06:46:12 515796 PM", "level": "INFO", "func_name": "__step", "lineno": 259, "filename": "tasks.py", "msg": {"msg": "`finally` of try-finally in `self.__step`.Custom-task-Task-1 set to none", "vars": {"task_name": "Custom-task-Task-1"}}}
{"datetime": "2025-07-30 06:46:12 515796 PM", "level": "INFO", "func_name": "__wakeup", "lineno": 401, "filename": "tasks.py", "msg": {"msg": "end of __wakeup. set self = None", "vars": {"task_name": "Custom-task-Task-1", "future_name": "Custom-task-Task-1: name: 1"}}}
{"datetime": "2025-07-30 06:46:12 611201 PM", "level": "INFO", "func_name": "__wakeup", "lineno": 377, "filename": "tasks.py", "msg": {"msg": "__wakeup entered", "vars": {"task_name": "Custom-task-Task-1", "future_name": "Custom-task-Task-1: name: 2", "future_state": "FINISHED"}}}
{"datetime": "2025-07-30 06:46:12 611201 PM", "level": "INFO", "func_name": "__wakeup", "lineno": 380, "filename": "tasks.py", "msg": {"msg": "will call future.result()", "vars": {"task_name": "Custom-task-Task-1", "future_name": "Custom-task-Task-1: name: 2"}}}
{"datetime": "2025-07-30 06:46:12 611201 PM", "level": "INFO", "func_name": "__wakeup", "lineno": 382, "filename": "tasks.py", "msg": {"msg": "__wakeup after future.result()", "vars": {"task_name": "Custom-task-Task-1", "future_name": "Custom-task-Task-1: name: 2", "future._state": "FINISHED"}}}
{"datetime": "2025-07-30 06:46:12 611201 PM", "level": "INFO", "func_name": "__wakeup", "lineno": 398, "filename": "tasks.py", "msg": {"msg": "__wakeup faced no exception when it called future.result()(Custom-task-Task-1: name: 2). calling again __step with no exc. I guess StopIteration will be raised", "vars": {"task_name": "Custom-task-Task-1", "future_name": "Custom-task-Task-1: name: 2"}}}
{"datetime": "2025-07-30 06:46:12 611201 PM", "level": "INFO", "func_name": "__step", "lineno": 231, "filename": "tasks.py", "msg": {"msg": "Entered self.__step", "method_signature": "__step(self, exc = None)", "vars": {"task_name": "Custom-task-Task-1", "exc": "None", "sent_from": "'_wakeup._else'"}}}
{"datetime": "2025-07-30 06:46:12 611201 PM", "level": "INFO", "func_name": "__step", "lineno": 241, "filename": "tasks.py", "msg": {"msg": "will initalized self._fut_waiter value", "vars": {"task_name": "Custom-task-Task-1"}}}
{"datetime": "2025-07-30 06:46:12 611201 PM", "level": "INFO", "func_name": "__step", "lineno": 243, "filename": "tasks.py", "msg": {"msg": "initalized self._fut_waiter to None", "vars": {"task_name": "Custom-task-Task-1"}}}
{"datetime": "2025-07-30 06:46:12 619422 PM", "level": "INFO", "func_name": "__step", "lineno": 248, "filename": "tasks.py", "msg": {"msg": "`try` of try-finally in `self.__step`. Call to __step_run_and_handle_request in next line.", "vars": {"task_name": "Custom-task-Task-1"}}}
{"datetime": "2025-07-30 06:46:12 620450 PM", "level": "INFO", "func_name": "__step_run_and_handle_result", "lineno": 262, "filename": "tasks.py", "msg": {"msg": "__step_run_and_handle_request entered", "method_signature": "__step_run_and_handle_result(self, exc)", "vars": {"task_name": "Custom-task-Task-1", "exc": "None"}}}
{"datetime": "2025-07-30 06:46:12 621438 PM", "level": "INFO", "func_name": "__step_run_and_handle_result", "lineno": 269, "filename": "tasks.py", "msg": {"msg": "`__step_run_and_hanle_result` main try-except exc is None so `coro.send()` in next line.", "vars": {"task_name": "Custom-task-Task-1"}}}
{"datetime": "2025-07-30 06:46:12 622018 PM", "level": "INFO", "func_name": "first", "lineno": 17, "filename": "understanding_tasks.py", "msg": "========== END ==========="}
{"datetime": "2025-07-30 06:46:12 622835 PM", "level": "INFO", "func_name": "__step_run_and_handle_result", "lineno": 282, "filename": "tasks.py", "msg": {"msg": "StopIteration exception encountered.", "vars": {"task_name": "Custom-task-Task-1", "future_name": "NO_AWAITABLE"}}}
{"datetime": "2025-07-30 06:46:12 623356 PM", "level": "INFO", "func_name": "__step_run_and_handle_result", "lineno": 291, "filename": "tasks.py", "msg": {"msg": "__step_run_and_handle_result StopIteration encountered but the task is not cancelled.", "vars": {"task_name": "Custom-task-Task-1", "exc.value": "None"}}}
{"datetime": "2025-07-30 06:46:12 624437 PM", "level": "INFO", "func_name": "__step_run_and_handle_result", "lineno": 294, "filename": "tasks.py", "msg": {"msg": "super().set_result(exc.value)", "vars": {"task_name": "Custom-task-Task-1"}}}
{"datetime": "2025-07-30 06:46:12 626444 PM", "level": "INFO", "func_name": "__step_run_and_handle_result", "lineno": 372, "filename": "tasks.py", "msg": {"msg": "self finally set to None", "vars": {"task_name": "Custom-task-Task-1"}}}
{"datetime": "2025-07-30 06:46:12 626444 PM", "level": "INFO", "func_name": "__step", "lineno": 250, "filename": "tasks.py", "msg": {"msg": "`try` of try-finally in `self.__step`. After __step_run_and_handle_result", "vars": {"task_name": "Custom-task-Task-1"}}}
{"datetime": "2025-07-30 06:46:12 626444 PM", "level": "INFO", "func_name": "__step", "lineno": 255, "filename": "tasks.py", "msg": {"msg": "`finally` of try-finally in `self.__step`. Call to _leave_task next and then set self to None", "vars": {"task_name": "Custom-task-Task-1"}}}
{"datetime": "2025-07-30 06:46:12 627660 PM", "level": "INFO", "func_name": "__step", "lineno": 259, "filename": "tasks.py", "msg": {"msg": "`finally` of try-finally in `self.__step`.Custom-task-Task-1 set to none", "vars": {"task_name": "Custom-task-Task-1"}}}
{"datetime": "2025-07-30 06:46:12 627660 PM", "level": "INFO", "func_name": "__wakeup", "lineno": 401, "filename": "tasks.py", "msg": {"msg": "end of __wakeup. set self = None", "vars": {"task_name": "Custom-task-Task-1", "future_name": "Custom-task-Task-1: name: 2"}}}
{"datetime": "2025-07-30 06:46:12 630251 PM", "level": "INFO", "func_name": "task_factory", "lineno": 407, "filename": "tasks.py", "msg": {"msg": "initalizing task", "vars": {"loop": "<ProactorEventLoop running=False closed=False debug=True>", "coro": "<coroutine object BaseEventLoop.shutdown_asyncgens at 0x000001e3f8e64040>", "task_name": null}}}
{"datetime": "2025-07-30 06:46:12 631261 PM", "level": "INFO", "func_name": "__init__", "lineno": 48, "filename": "tasks.py", "msg": {"msg": "__init__ initalized"}}
{"datetime": "2025-07-30 06:46:12 632244 PM", "level": "INFO", "func_name": "__init__", "lineno": 76, "filename": "tasks.py", "msg": {"msg": "self.__step scheduled on EVENT_LOOP in __init__", "vars": {"task_name": "Custom-task-Task-3"}}}
{"datetime": "2025-07-30 06:46:12 633564 PM", "level": "INFO", "func_name": "__init__", "lineno": 78, "filename": "tasks.py", "msg": {"msg": "__init__ after scheduling __step on EVENT_LOOP using loop.call_soon", "vars": {"task_name": "Custom-task-Task-3"}}}
{"datetime": "2025-07-30 06:46:12 633564 PM", "level": "INFO", "func_name": "__step", "lineno": 231, "filename": "tasks.py", "msg": {"msg": "Entered self.__step", "method_signature": "__step(self, exc = None)", "vars": {"task_name": "Custom-task-Task-3", "exc": "None", "sent_from": "'__init__'"}}}
{"datetime": "2025-07-30 06:46:12 634708 PM", "level": "INFO", "func_name": "__step", "lineno": 241, "filename": "tasks.py", "msg": {"msg": "will initalized self._fut_waiter value", "vars": {"task_name": "Custom-task-Task-3"}}}
{"datetime": "2025-07-30 06:46:12 634708 PM", "level": "INFO", "func_name": "__step", "lineno": 243, "filename": "tasks.py", "msg": {"msg": "initalized self._fut_waiter to None", "vars": {"task_name": "Custom-task-Task-3"}}}
{"datetime": "2025-07-30 06:46:12 635682 PM", "level": "INFO", "func_name": "__step", "lineno": 248, "filename": "tasks.py", "msg": {"msg": "`try` of try-finally in `self.__step`. Call to __step_run_and_handle_request in next line.", "vars": {"task_name": "Custom-task-Task-3"}}}
{"datetime": "2025-07-30 06:46:12 635682 PM", "level": "INFO", "func_name": "__step_run_and_handle_result", "lineno": 262, "filename": "tasks.py", "msg": {"msg": "__step_run_and_handle_request entered", "method_signature": "__step_run_and_handle_result(self, exc)", "vars": {"task_name": "Custom-task-Task-3", "exc": "None"}}}
{"datetime": "2025-07-30 06:46:12 635682 PM", "level": "INFO", "func_name": "__step_run_and_handle_result", "lineno": 269, "filename": "tasks.py", "msg": {"msg": "`__step_run_and_hanle_result` main try-except exc is None so `coro.send()` in next line.", "vars": {"task_name": "Custom-task-Task-3"}}}
{"datetime": "2025-07-30 06:46:12 635682 PM", "level": "INFO", "func_name": "__step_run_and_handle_result", "lineno": 282, "filename": "tasks.py", "msg": {"msg": "StopIteration exception encountered.", "vars": {"task_name": "Custom-task-Task-3", "future_name": "NO_AWAITABLE"}}}
{"datetime": "2025-07-30 06:46:12 636680 PM", "level": "INFO", "func_name": "__step_run_and_handle_result", "lineno": 291, "filename": "tasks.py", "msg": {"msg": "__step_run_and_handle_result StopIteration encountered but the task is not cancelled.", "vars": {"task_name": "Custom-task-Task-3", "exc.value": "None"}}}
{"datetime": "2025-07-30 06:46:12 637682 PM", "level": "INFO", "func_name": "__step_run_and_handle_result", "lineno": 294, "filename": "tasks.py", "msg": {"msg": "super().set_result(exc.value)", "vars": {"task_name": "Custom-task-Task-3"}}}
{"datetime": "2025-07-30 06:46:12 637682 PM", "level": "INFO", "func_name": "__step_run_and_handle_result", "lineno": 372, "filename": "tasks.py", "msg": {"msg": "self finally set to None", "vars": {"task_name": "Custom-task-Task-3"}}}
{"datetime": "2025-07-30 06:46:12 638155 PM", "level": "INFO", "func_name": "__step", "lineno": 250, "filename": "tasks.py", "msg": {"msg": "`try` of try-finally in `self.__step`. After __step_run_and_handle_result", "vars": {"task_name": "Custom-task-Task-3"}}}
{"datetime": "2025-07-30 06:46:12 638155 PM", "level": "INFO", "func_name": "__step", "lineno": 255, "filename": "tasks.py", "msg": {"msg": "`finally` of try-finally in `self.__step`. Call to _leave_task next and then set self to None", "vars": {"task_name": "Custom-task-Task-3"}}}
{"datetime": "2025-07-30 06:46:12 638888 PM", "level": "INFO", "func_name": "__step", "lineno": 259, "filename": "tasks.py", "msg": {"msg": "`finally` of try-finally in `self.__step`.Custom-task-Task-3 set to none", "vars": {"task_name": "Custom-task-Task-3"}}}
{"datetime": "2025-07-30 06:46:12 639926 PM", "level": "INFO", "func_name": "task_factory", "lineno": 407, "filename": "tasks.py", "msg": {"msg": "initalizing task", "vars": {"loop": "<ProactorEventLoop running=False closed=False debug=True>", "coro": "<coroutine object BaseEventLoop.shutdown_default_executor at 0x000001e3f8dce740>", "task_name": null}}}
{"datetime": "2025-07-30 06:46:12 639926 PM", "level": "INFO", "func_name": "__init__", "lineno": 48, "filename": "tasks.py", "msg": {"msg": "__init__ initalized"}}
{"datetime": "2025-07-30 06:46:12 640894 PM", "level": "INFO", "func_name": "__init__", "lineno": 76, "filename": "tasks.py", "msg": {"msg": "self.__step scheduled on EVENT_LOOP in __init__", "vars": {"task_name": "Custom-task-Task-4"}}}
{"datetime": "2025-07-30 06:46:12 640894 PM", "level": "INFO", "func_name": "__init__", "lineno": 78, "filename": "tasks.py", "msg": {"msg": "__init__ after scheduling __step on EVENT_LOOP using loop.call_soon", "vars": {"task_name": "Custom-task-Task-4"}}}
{"datetime": "2025-07-30 06:46:12 641902 PM", "level": "INFO", "func_name": "__step", "lineno": 231, "filename": "tasks.py", "msg": {"msg": "Entered self.__step", "method_signature": "__step(self, exc = None)", "vars": {"task_name": "Custom-task-Task-4", "exc": "None", "sent_from": "'__init__'"}}}
{"datetime": "2025-07-30 06:46:12 641902 PM", "level": "INFO", "func_name": "__step", "lineno": 241, "filename": "tasks.py", "msg": {"msg": "will initalized self._fut_waiter value", "vars": {"task_name": "Custom-task-Task-4"}}}
{"datetime": "2025-07-30 06:46:12 642776 PM", "level": "INFO", "func_name": "__step", "lineno": 243, "filename": "tasks.py", "msg": {"msg": "initalized self._fut_waiter to None", "vars": {"task_name": "Custom-task-Task-4"}}}
{"datetime": "2025-07-30 06:46:12 642776 PM", "level": "INFO", "func_name": "__step", "lineno": 248, "filename": "tasks.py", "msg": {"msg": "`try` of try-finally in `self.__step`. Call to __step_run_and_handle_request in next line.", "vars": {"task_name": "Custom-task-Task-4"}}}
{"datetime": "2025-07-30 06:46:12 643355 PM", "level": "INFO", "func_name": "__step_run_and_handle_result", "lineno": 262, "filename": "tasks.py", "msg": {"msg": "__step_run_and_handle_request entered", "method_signature": "__step_run_and_handle_result(self, exc)", "vars": {"task_name": "Custom-task-Task-4", "exc": "None"}}}
{"datetime": "2025-07-30 06:46:12 643355 PM", "level": "INFO", "func_name": "__step_run_and_handle_result", "lineno": 269, "filename": "tasks.py", "msg": {"msg": "`__step_run_and_hanle_result` main try-except exc is None so `coro.send()` in next line.", "vars": {"task_name": "Custom-task-Task-4"}}}
{"datetime": "2025-07-30 06:46:12 644362 PM", "level": "INFO", "func_name": "__step_run_and_handle_result", "lineno": 282, "filename": "tasks.py", "msg": {"msg": "StopIteration exception encountered.", "vars": {"task_name": "Custom-task-Task-4", "future_name": "NO_AWAITABLE"}}}
{"datetime": "2025-07-30 06:46:12 644362 PM", "level": "INFO", "func_name": "__step_run_and_handle_result", "lineno": 291, "filename": "tasks.py", "msg": {"msg": "__step_run_and_handle_result StopIteration encountered but the task is not cancelled.", "vars": {"task_name": "Custom-task-Task-4", "exc.value": "None"}}}
{"datetime": "2025-07-30 06:46:12 644362 PM", "level": "INFO", "func_name": "__step_run_and_handle_result", "lineno": 294, "filename": "tasks.py", "msg": {"msg": "super().set_result(exc.value)", "vars": {"task_name": "Custom-task-Task-4"}}}
{"datetime": "2025-07-30 06:46:12 645361 PM", "level": "INFO", "func_name": "__step_run_and_handle_result", "lineno": 372, "filename": "tasks.py", "msg": {"msg": "self finally set to None", "vars": {"task_name": "Custom-task-Task-4"}}}
{"datetime": "2025-07-30 06:46:12 645361 PM", "level": "INFO", "func_name": "__step", "lineno": 250, "filename": "tasks.py", "msg": {"msg": "`try` of try-finally in `self.__step`. After __step_run_and_handle_result", "vars": {"task_name": "Custom-task-Task-4"}}}
{"datetime": "2025-07-30 06:46:12 645361 PM", "level": "INFO", "func_name": "__step", "lineno": 255, "filename": "tasks.py", "msg": {"msg": "`finally` of try-finally in `self.__step`. Call to _leave_task next and then set self to None", "vars": {"task_name": "Custom-task-Task-4"}}}
{"datetime": "2025-07-30 06:46:12 646098 PM", "level": "INFO", "func_name": "__step", "lineno": 259, "filename": "tasks.py", "msg": {"msg": "`finally` of try-finally in `self.__step`.Custom-task-Task-4 set to none", "vars": {"task_name": "Custom-task-Task-4"}}}
