{"datetime": "2025-07-30 06:45:10 508860 PM", "level": "INFO", "func_name": "main", "lineno": 40, "filename": "understanding_tasks.py", "msg": "Main function calling"}
{"datetime": "2025-07-30 06:45:10 508860 PM", "level": "INFO", "func_name": "task_factory", "lineno": 407, "filename": "tasks.py", "msg": {"msg": "initalizing task", "vars": {"loop": "<ProactorEventLoop running=True closed=False debug=True>", "coro": "<coroutine object first at 0x00000198acbbc280>", "task_name": null}}}
{"datetime": "2025-07-30 06:45:10 508860 PM", "level": "INFO", "func_name": "__init__", "lineno": 48, "filename": "tasks.py", "msg": {"msg": "__init__ initalized"}}
{"datetime": "2025-07-30 06:45:10 508860 PM", "level": "INFO", "func_name": "__init__", "lineno": 76, "filename": "tasks.py", "msg": {"msg": "self.__step scheduled on EVENT_LOOP in __init__", "vars": {"task_name": "Custom-task-Task-1"}}}
{"datetime": "2025-07-30 06:45:10 508860 PM", "level": "INFO", "func_name": "__init__", "lineno": 78, "filename": "tasks.py", "msg": {"msg": "__init__ after scheduling __step on EVENT_LOOP using loop.call_soon", "vars": {"task_name": "Custom-task-Task-1"}}}
{"datetime": "2025-07-30 06:45:10 508860 PM", "level": "INFO", "func_name": "task_factory", "lineno": 407, "filename": "tasks.py", "msg": {"msg": "initalizing task", "vars": {"loop": "<ProactorEventLoop running=True closed=False debug=True>", "coro": "<coroutine object second at 0x00000198acbbc340>", "task_name": null}}}
{"datetime": "2025-07-30 06:45:10 508860 PM", "level": "INFO", "func_name": "__init__", "lineno": 48, "filename": "tasks.py", "msg": {"msg": "__init__ initalized"}}
{"datetime": "2025-07-30 06:45:10 508860 PM", "level": "INFO", "func_name": "__init__", "lineno": 76, "filename": "tasks.py", "msg": {"msg": "self.__step scheduled on EVENT_LOOP in __init__", "vars": {"task_name": "Custom-task-Task-2"}}}
{"datetime": "2025-07-30 06:45:10 508860 PM", "level": "INFO", "func_name": "__init__", "lineno": 78, "filename": "tasks.py", "msg": {"msg": "__init__ after scheduling __step on EVENT_LOOP using loop.call_soon", "vars": {"task_name": "Custom-task-Task-2"}}}
{"datetime": "2025-07-30 06:45:10 508860 PM", "level": "INFO", "func_name": "task_factory", "lineno": 407, "filename": "tasks.py", "msg": {"msg": "initalizing task", "vars": {"loop": "<ProactorEventLoop running=True closed=False debug=True>", "coro": "<coroutine object third at 0x00000198acbbc400>", "task_name": null}}}
{"datetime": "2025-07-30 06:45:10 508860 PM", "level": "INFO", "func_name": "__init__", "lineno": 48, "filename": "tasks.py", "msg": {"msg": "__init__ initalized"}}
{"datetime": "2025-07-30 06:45:10 508860 PM", "level": "INFO", "func_name": "__init__", "lineno": 76, "filename": "tasks.py", "msg": {"msg": "self.__step scheduled on EVENT_LOOP in __init__", "vars": {"task_name": "Custom-task-Task-3"}}}
{"datetime": "2025-07-30 06:45:10 517635 PM", "level": "INFO", "func_name": "__init__", "lineno": 78, "filename": "tasks.py", "msg": {"msg": "__init__ after scheduling __step on EVENT_LOOP using loop.call_soon", "vars": {"task_name": "Custom-task-Task-3"}}}
{"datetime": "2025-07-30 06:45:10 522229 PM", "level": "INFO", "func_name": "__step", "lineno": 231, "filename": "tasks.py", "msg": {"msg": "Entered self.__step", "method_signature": "__step(self, exc = None)", "vars": {"task_name": "Custom-task-Task-1", "exc": "None", "sent_from": "'__init__'"}}}
{"datetime": "2025-07-30 06:45:10 522229 PM", "level": "INFO", "func_name": "__step", "lineno": 241, "filename": "tasks.py", "msg": {"msg": "will initalized self._fut_waiter value", "vars": {"task_name": "Custom-task-Task-1"}}}
{"datetime": "2025-07-30 06:45:10 523818 PM", "level": "INFO", "func_name": "__step", "lineno": 243, "filename": "tasks.py", "msg": {"msg": "initalized self._fut_waiter to None", "vars": {"task_name": "Custom-task-Task-1"}}}
{"datetime": "2025-07-30 06:45:10 523818 PM", "level": "INFO", "func_name": "__step", "lineno": 248, "filename": "tasks.py", "msg": {"msg": "`try` of try-finally in `self.__step`. Call to __step_run_and_handle_request in next line.", "vars": {"task_name": "Custom-task-Task-1"}}}
{"datetime": "2025-07-30 06:45:10 524848 PM", "level": "INFO", "func_name": "__step_run_and_handle_result", "lineno": 262, "filename": "tasks.py", "msg": {"msg": "__step_run_and_handle_request entered", "method_signature": "__step_run_and_handle_result(self, exc)", "vars": {"task_name": "Custom-task-Task-1", "exc": "None"}}}
{"datetime": "2025-07-30 06:45:10 524848 PM", "level": "INFO", "func_name": "__step_run_and_handle_result", "lineno": 269, "filename": "tasks.py", "msg": {"msg": "`__step_run_and_hanle_result` main try-except exc is None so `coro.send()` in next line.", "vars": {"task_name": "Custom-task-Task-1"}}}
{"datetime": "2025-07-30 06:45:10 525851 PM", "level": "INFO", "func_name": "first", "lineno": 11, "filename": "understanding_tasks.py", "msg": "======== FIRST.FIRST ==================="}
{"datetime": "2025-07-30 06:45:10 529879 PM", "level": "INFO", "func_name": "__step_run_and_handle_result", "lineno": 272, "filename": "tasks.py", "msg": {"msg:": "__step_run_and_handle_result main try-except after `coro.send()`", "vars": {"task_name": "Custom-task-Task-1"}}}
{"datetime": "2025-07-30 06:45:10 530862 PM", "level": "INFO", "func_name": "__step_run_and_handle_result", "lineno": 310, "filename": "tasks.py", "msg": {"msg": "try-else in __step_run_and_handle_result", "vars": {"task_name": "Custom-task-Task-1", "future_name": "Custom-task-Task-1: name: 1", "result": "<Future pending created at C:\\msys64\\mingw64\\lib\\python3.12\\asyncio\\base_events.py:448>", "is_asyncio_future_blocking": "getattr(result,\"_asyncio_future_blocking\", None)= True"}}}
{"datetime": "2025-07-30 06:45:10 530862 PM", "level": "INFO", "func_name": "__step_run_and_handle_result", "lineno": 313, "filename": "tasks.py", "msg": {"msg": "is_future blocking", "vars": {"task_name": "Custom-task-Task-1", "future_name": "Custom-task-Task-1: name: 1", "is_future_blocking": true}}}
{"datetime": "2025-07-30 06:45:10 531862 PM", "level": "INFO", "func_name": "__step_run_and_handle_result", "lineno": 330, "filename": "tasks.py", "msg": {"msg": "scheduling on EVENT_LOOP callback to fututre.add_done_call_back", "vars": {"task_name": "Custom-task-Task-1", "future_name": "Custom-task-Task-1: name: 1", "future_state": "PENDING", "result": "<Future pending created at C:\\msys64\\mingw64\\lib\\python3.12\\asyncio\\base_events.py:448>"}}}
{"datetime": "2025-07-30 06:45:10 532369 PM", "level": "INFO", "func_name": "__step_run_and_handle_result", "lineno": 335, "filename": "tasks.py", "msg": {"msg": "After scheduling callbacks to fut. self._future_wait = result", "vars": {"task_name": "Custom-task-Task-1", "future_name": "Custom-task-Task-1: name: 1", "result": "<Future pending cb=[Task.__wakeup()] created at C:\\msys64\\mingw64\\lib\\python3.12\\asyncio\\base_events.py:448>", "self._fut_waiter": null, "future_state": "PENDING", "future_callbacks_list(fut._callbacks)": "[(<bound method Task.__wakeup of <Task pending name='Custom-task-Task-1' coro=<first() running at c:/Users/shaik/learning/concurrency/python_concurrency/understanding_tasks.py:12> cb=[gather.<locals>._done_callback() at C:\\msys64\\mingw64\\lib\\python3.12\\asyncio\\tasks.py:767] created at c:\\Users\\shaik\\learning\\concurrency\\python_concurrency\\experiments\\tasks.py:410>>, <_contextvars.Context object at 0x00000198ac24b5c0>)]"}}}
{"datetime": "2025-07-30 06:45:10 533389 PM", "level": "INFO", "func_name": "__step_run_and_handle_result", "lineno": 340, "filename": "tasks.py", "msg": {"msg": "self._fut_waiter set to result", "vars": {"task_name": "Custom-task-Task-1", "future_name": "Custom-task-Task-1: name: 1", "future_state": "PENDING", "self._fut_waiter": "<Future pending cb=[Task.__wakeup()] created at C:\\msys64\\mingw64\\lib\\python3.12\\asyncio\\base_events.py:448>"}}}
{"datetime": "2025-07-30 06:45:10 533389 PM", "level": "INFO", "func_name": "__step_run_and_handle_result", "lineno": 372, "filename": "tasks.py", "msg": {"msg": "self finally set to None", "vars": {"task_name": "Custom-task-Task-1"}}}
{"datetime": "2025-07-30 06:45:10 534388 PM", "level": "INFO", "func_name": "__step", "lineno": 250, "filename": "tasks.py", "msg": {"msg": "`try` of try-finally in `self.__step`. After __step_run_and_handle_result", "vars": {"task_name": "Custom-task-Task-1"}}}
{"datetime": "2025-07-30 06:45:10 535381 PM", "level": "INFO", "func_name": "__step", "lineno": 255, "filename": "tasks.py", "msg": {"msg": "`finally` of try-finally in `self.__step`. Call to _leave_task next and then set self to None", "vars": {"task_name": "Custom-task-Task-1"}}}
{"datetime": "2025-07-30 06:45:10 535381 PM", "level": "INFO", "func_name": "__step", "lineno": 259, "filename": "tasks.py", "msg": {"msg": "`finally` of try-finally in `self.__step`.Custom-task-Task-1 set to none", "vars": {"task_name": "Custom-task-Task-1"}}}
{"datetime": "2025-07-30 06:45:10 536379 PM", "level": "INFO", "func_name": "__step", "lineno": 231, "filename": "tasks.py", "msg": {"msg": "Entered self.__step", "method_signature": "__step(self, exc = None)", "vars": {"task_name": "Custom-task-Task-2", "exc": "None", "sent_from": "'__init__'"}}}
{"datetime": "2025-07-30 06:45:10 536763 PM", "level": "INFO", "func_name": "__step", "lineno": 241, "filename": "tasks.py", "msg": {"msg": "will initalized self._fut_waiter value", "vars": {"task_name": "Custom-task-Task-2"}}}
{"datetime": "2025-07-30 06:45:10 536763 PM", "level": "INFO", "func_name": "__step", "lineno": 243, "filename": "tasks.py", "msg": {"msg": "initalized self._fut_waiter to None", "vars": {"task_name": "Custom-task-Task-2"}}}
{"datetime": "2025-07-30 06:45:10 536763 PM", "level": "INFO", "func_name": "__step", "lineno": 248, "filename": "tasks.py", "msg": {"msg": "`try` of try-finally in `self.__step`. Call to __step_run_and_handle_request in next line.", "vars": {"task_name": "Custom-task-Task-2"}}}
{"datetime": "2025-07-30 06:45:10 536763 PM", "level": "INFO", "func_name": "__step_run_and_handle_result", "lineno": 262, "filename": "tasks.py", "msg": {"msg": "__step_run_and_handle_request entered", "method_signature": "__step_run_and_handle_result(self, exc)", "vars": {"task_name": "Custom-task-Task-2", "exc": "None"}}}
{"datetime": "2025-07-30 06:45:10 536763 PM", "level": "INFO", "func_name": "__step_run_and_handle_result", "lineno": 269, "filename": "tasks.py", "msg": {"msg": "`__step_run_and_hanle_result` main try-except exc is None so `coro.send()` in next line.", "vars": {"task_name": "Custom-task-Task-2"}}}
{"datetime": "2025-07-30 06:45:10 536763 PM", "level": "INFO", "func_name": "second", "lineno": 20, "filename": "understanding_tasks.py", "msg": "======== SECOND.FIRST ==================="}
{"datetime": "2025-07-30 06:45:10 536763 PM", "level": "INFO", "func_name": "__step_run_and_handle_result", "lineno": 272, "filename": "tasks.py", "msg": {"msg:": "__step_run_and_handle_result main try-except after `coro.send()`", "vars": {"task_name": "Custom-task-Task-2"}}}
{"datetime": "2025-07-30 06:45:10 536763 PM", "level": "INFO", "func_name": "__step_run_and_handle_result", "lineno": 310, "filename": "tasks.py", "msg": {"msg": "try-else in __step_run_and_handle_result", "vars": {"task_name": "Custom-task-Task-2", "future_name": "Custom-task-Task-2: name: 1", "result": "<Future pending created at C:\\msys64\\mingw64\\lib\\python3.12\\asyncio\\base_events.py:448>", "is_asyncio_future_blocking": "getattr(result,\"_asyncio_future_blocking\", None)= True"}}}
{"datetime": "2025-07-30 06:45:10 536763 PM", "level": "INFO", "func_name": "__step_run_and_handle_result", "lineno": 313, "filename": "tasks.py", "msg": {"msg": "is_future blocking", "vars": {"task_name": "Custom-task-Task-2", "future_name": "Custom-task-Task-2: name: 1", "is_future_blocking": true}}}
{"datetime": "2025-07-30 06:45:10 536763 PM", "level": "INFO", "func_name": "__step_run_and_handle_result", "lineno": 330, "filename": "tasks.py", "msg": {"msg": "scheduling on EVENT_LOOP callback to fututre.add_done_call_back", "vars": {"task_name": "Custom-task-Task-2", "future_name": "Custom-task-Task-2: name: 1", "future_state": "PENDING", "result": "<Future pending created at C:\\msys64\\mingw64\\lib\\python3.12\\asyncio\\base_events.py:448>"}}}
{"datetime": "2025-07-30 06:45:10 540889 PM", "level": "INFO", "func_name": "__step_run_and_handle_result", "lineno": 335, "filename": "tasks.py", "msg": {"msg": "After scheduling callbacks to fut. self._future_wait = result", "vars": {"task_name": "Custom-task-Task-2", "future_name": "Custom-task-Task-2: name: 1", "result": "<Future pending cb=[Task.__wakeup()] created at C:\\msys64\\mingw64\\lib\\python3.12\\asyncio\\base_events.py:448>", "self._fut_waiter": null, "future_state": "PENDING", "future_callbacks_list(fut._callbacks)": "[(<bound method Task.__wakeup of <Task pending name='Custom-task-Task-2' coro=<second() running at c:/Users/shaik/learning/concurrency/python_concurrency/understanding_tasks.py:21> cb=[gather.<locals>._done_callback() at C:\\msys64\\mingw64\\lib\\python3.12\\asyncio\\tasks.py:767] created at c:\\Users\\shaik\\learning\\concurrency\\python_concurrency\\experiments\\tasks.py:410>>, <_contextvars.Context object at 0x00000198acbe6040>)]"}}}
{"datetime": "2025-07-30 06:45:10 540889 PM", "level": "INFO", "func_name": "__step_run_and_handle_result", "lineno": 340, "filename": "tasks.py", "msg": {"msg": "self._fut_waiter set to result", "vars": {"task_name": "Custom-task-Task-2", "future_name": "Custom-task-Task-2: name: 1", "future_state": "PENDING", "self._fut_waiter": "<Future pending cb=[Task.__wakeup()] created at C:\\msys64\\mingw64\\lib\\python3.12\\asyncio\\base_events.py:448>"}}}
{"datetime": "2025-07-30 06:45:10 540889 PM", "level": "INFO", "func_name": "__step_run_and_handle_result", "lineno": 372, "filename": "tasks.py", "msg": {"msg": "self finally set to None", "vars": {"task_name": "Custom-task-Task-2"}}}
{"datetime": "2025-07-30 06:45:10 540889 PM", "level": "INFO", "func_name": "__step", "lineno": 250, "filename": "tasks.py", "msg": {"msg": "`try` of try-finally in `self.__step`. After __step_run_and_handle_result", "vars": {"task_name": "Custom-task-Task-2"}}}
{"datetime": "2025-07-30 06:45:10 542347 PM", "level": "INFO", "func_name": "__step", "lineno": 255, "filename": "tasks.py", "msg": {"msg": "`finally` of try-finally in `self.__step`. Call to _leave_task next and then set self to None", "vars": {"task_name": "Custom-task-Task-2"}}}
{"datetime": "2025-07-30 06:45:10 542347 PM", "level": "INFO", "func_name": "__step", "lineno": 259, "filename": "tasks.py", "msg": {"msg": "`finally` of try-finally in `self.__step`.Custom-task-Task-2 set to none", "vars": {"task_name": "Custom-task-Task-2"}}}
{"datetime": "2025-07-30 06:45:10 542347 PM", "level": "INFO", "func_name": "__step", "lineno": 231, "filename": "tasks.py", "msg": {"msg": "Entered self.__step", "method_signature": "__step(self, exc = None)", "vars": {"task_name": "Custom-task-Task-3", "exc": "None", "sent_from": "'__init__'"}}}
{"datetime": "2025-07-30 06:45:10 542347 PM", "level": "INFO", "func_name": "__step", "lineno": 241, "filename": "tasks.py", "msg": {"msg": "will initalized self._fut_waiter value", "vars": {"task_name": "Custom-task-Task-3"}}}
{"datetime": "2025-07-30 06:45:10 542347 PM", "level": "INFO", "func_name": "__step", "lineno": 243, "filename": "tasks.py", "msg": {"msg": "initalized self._fut_waiter to None", "vars": {"task_name": "Custom-task-Task-3"}}}
{"datetime": "2025-07-30 06:45:10 543604 PM", "level": "INFO", "func_name": "__step", "lineno": 248, "filename": "tasks.py", "msg": {"msg": "`try` of try-finally in `self.__step`. Call to __step_run_and_handle_request in next line.", "vars": {"task_name": "Custom-task-Task-3"}}}
{"datetime": "2025-07-30 06:45:10 543604 PM", "level": "INFO", "func_name": "__step_run_and_handle_result", "lineno": 262, "filename": "tasks.py", "msg": {"msg": "__step_run_and_handle_request entered", "method_signature": "__step_run_and_handle_result(self, exc)", "vars": {"task_name": "Custom-task-Task-3", "exc": "None"}}}
{"datetime": "2025-07-30 06:45:10 543604 PM", "level": "INFO", "func_name": "__step_run_and_handle_result", "lineno": 269, "filename": "tasks.py", "msg": {"msg": "`__step_run_and_hanle_result` main try-except exc is None so `coro.send()` in next line.", "vars": {"task_name": "Custom-task-Task-3"}}}
{"datetime": "2025-07-30 06:45:10 544604 PM", "level": "INFO", "func_name": "third", "lineno": 29, "filename": "understanding_tasks.py", "msg": "======== SECOND.FIRST ==================="}
{"datetime": "2025-07-30 06:45:10 545605 PM", "level": "INFO", "func_name": "__step_run_and_handle_result", "lineno": 272, "filename": "tasks.py", "msg": {"msg:": "__step_run_and_handle_result main try-except after `coro.send()`", "vars": {"task_name": "Custom-task-Task-3"}}}
{"datetime": "2025-07-30 06:45:10 545605 PM", "level": "INFO", "func_name": "__step_run_and_handle_result", "lineno": 310, "filename": "tasks.py", "msg": {"msg": "try-else in __step_run_and_handle_result", "vars": {"task_name": "Custom-task-Task-3", "future_name": "Custom-task-Task-3: name: 1", "result": "<Future pending created at C:\\msys64\\mingw64\\lib\\python3.12\\asyncio\\base_events.py:448>", "is_asyncio_future_blocking": "getattr(result,\"_asyncio_future_blocking\", None)= True"}}}
{"datetime": "2025-07-30 06:45:10 546603 PM", "level": "INFO", "func_name": "__step_run_and_handle_result", "lineno": 313, "filename": "tasks.py", "msg": {"msg": "is_future blocking", "vars": {"task_name": "Custom-task-Task-3", "future_name": "Custom-task-Task-3: name: 1", "is_future_blocking": true}}}
{"datetime": "2025-07-30 06:45:10 546603 PM", "level": "INFO", "func_name": "__step_run_and_handle_result", "lineno": 330, "filename": "tasks.py", "msg": {"msg": "scheduling on EVENT_LOOP callback to fututre.add_done_call_back", "vars": {"task_name": "Custom-task-Task-3", "future_name": "Custom-task-Task-3: name: 1", "future_state": "PENDING", "result": "<Future pending created at C:\\msys64\\mingw64\\lib\\python3.12\\asyncio\\base_events.py:448>"}}}
{"datetime": "2025-07-30 06:45:10 546603 PM", "level": "INFO", "func_name": "__step_run_and_handle_result", "lineno": 335, "filename": "tasks.py", "msg": {"msg": "After scheduling callbacks to fut. self._future_wait = result", "vars": {"task_name": "Custom-task-Task-3", "future_name": "Custom-task-Task-3: name: 1", "result": "<Future pending cb=[Task.__wakeup()] created at C:\\msys64\\mingw64\\lib\\python3.12\\asyncio\\base_events.py:448>", "self._fut_waiter": null, "future_state": "PENDING", "future_callbacks_list(fut._callbacks)": "[(<bound method Task.__wakeup of <Task pending name='Custom-task-Task-3' coro=<third() running at c:/Users/shaik/learning/concurrency/python_concurrency/understanding_tasks.py:30> cb=[gather.<locals>._done_callback() at C:\\msys64\\mingw64\\lib\\python3.12\\asyncio\\tasks.py:767] created at c:\\Users\\shaik\\learning\\concurrency\\python_concurrency\\experiments\\tasks.py:410>>, <_contextvars.Context object at 0x00000198acbe63c0>)]"}}}
{"datetime": "2025-07-30 06:45:10 547642 PM", "level": "INFO", "func_name": "__step_run_and_handle_result", "lineno": 340, "filename": "tasks.py", "msg": {"msg": "self._fut_waiter set to result", "vars": {"task_name": "Custom-task-Task-3", "future_name": "Custom-task-Task-3: name: 1", "future_state": "PENDING", "self._fut_waiter": "<Future pending cb=[Task.__wakeup()] created at C:\\msys64\\mingw64\\lib\\python3.12\\asyncio\\base_events.py:448>"}}}
{"datetime": "2025-07-30 06:45:10 547642 PM", "level": "INFO", "func_name": "__step_run_and_handle_result", "lineno": 372, "filename": "tasks.py", "msg": {"msg": "self finally set to None", "vars": {"task_name": "Custom-task-Task-3"}}}
{"datetime": "2025-07-30 06:45:10 547642 PM", "level": "INFO", "func_name": "__step", "lineno": 250, "filename": "tasks.py", "msg": {"msg": "`try` of try-finally in `self.__step`. After __step_run_and_handle_result", "vars": {"task_name": "Custom-task-Task-3"}}}
{"datetime": "2025-07-30 06:45:10 548510 PM", "level": "INFO", "func_name": "__step", "lineno": 255, "filename": "tasks.py", "msg": {"msg": "`finally` of try-finally in `self.__step`. Call to _leave_task next and then set self to None", "vars": {"task_name": "Custom-task-Task-3"}}}
{"datetime": "2025-07-30 06:45:10 548510 PM", "level": "INFO", "func_name": "__step", "lineno": 259, "filename": "tasks.py", "msg": {"msg": "`finally` of try-finally in `self.__step`.Custom-task-Task-3 set to none", "vars": {"task_name": "Custom-task-Task-3"}}}
{"datetime": "2025-07-30 06:45:11 049784 PM", "level": "INFO", "func_name": "__wakeup", "lineno": 377, "filename": "tasks.py", "msg": {"msg": "__wakeup entered", "vars": {"task_name": "Custom-task-Task-2", "future_name": "Custom-task-Task-2: name: 1", "future_state": "FINISHED"}}}
{"datetime": "2025-07-30 06:45:11 050878 PM", "level": "INFO", "func_name": "__wakeup", "lineno": 380, "filename": "tasks.py", "msg": {"msg": "will call future.result()", "vars": {"task_name": "Custom-task-Task-2", "future_name": "Custom-task-Task-2: name: 1"}}}
{"datetime": "2025-07-30 06:45:11 052691 PM", "level": "INFO", "func_name": "__wakeup", "lineno": 382, "filename": "tasks.py", "msg": {"msg": "__wakeup after future.result()", "vars": {"task_name": "Custom-task-Task-2", "future_name": "Custom-task-Task-2: name: 1", "future._state": "FINISHED"}}}
{"datetime": "2025-07-30 06:45:11 053760 PM", "level": "INFO", "func_name": "__wakeup", "lineno": 398, "filename": "tasks.py", "msg": {"msg": "__wakeup faced no exception when it called future.result()(Custom-task-Task-2: name: 1). calling again __step with no exc. I guess StopIteration will be raised", "vars": {"task_name": "Custom-task-Task-2", "future_name": "Custom-task-Task-2: name: 1"}}}
{"datetime": "2025-07-30 06:45:11 055397 PM", "level": "INFO", "func_name": "__step", "lineno": 231, "filename": "tasks.py", "msg": {"msg": "Entered self.__step", "method_signature": "__step(self, exc = None)", "vars": {"task_name": "Custom-task-Task-2", "exc": "None", "sent_from": "'_wakeup._else'"}}}
{"datetime": "2025-07-30 06:45:11 055397 PM", "level": "INFO", "func_name": "__step", "lineno": 241, "filename": "tasks.py", "msg": {"msg": "will initalized self._fut_waiter value", "vars": {"task_name": "Custom-task-Task-2"}}}
{"datetime": "2025-07-30 06:45:11 055397 PM", "level": "INFO", "func_name": "__step", "lineno": 243, "filename": "tasks.py", "msg": {"msg": "initalized self._fut_waiter to None", "vars": {"task_name": "Custom-task-Task-2"}}}
{"datetime": "2025-07-30 06:45:11 055397 PM", "level": "INFO", "func_name": "__step", "lineno": 248, "filename": "tasks.py", "msg": {"msg": "`try` of try-finally in `self.__step`. Call to __step_run_and_handle_request in next line.", "vars": {"task_name": "Custom-task-Task-2"}}}
{"datetime": "2025-07-30 06:45:11 055397 PM", "level": "INFO", "func_name": "__step_run_and_handle_result", "lineno": 262, "filename": "tasks.py", "msg": {"msg": "__step_run_and_handle_request entered", "method_signature": "__step_run_and_handle_result(self, exc)", "vars": {"task_name": "Custom-task-Task-2", "exc": "None"}}}
{"datetime": "2025-07-30 06:45:11 060777 PM", "level": "INFO", "func_name": "__step_run_and_handle_result", "lineno": 269, "filename": "tasks.py", "msg": {"msg": "`__step_run_and_hanle_result` main try-except exc is None so `coro.send()` in next line.", "vars": {"task_name": "Custom-task-Task-2"}}}
{"datetime": "2025-07-30 06:45:11 060777 PM", "level": "INFO", "func_name": "second", "lineno": 22, "filename": "understanding_tasks.py", "msg": "========= SECOND.SECOND ========================="}
{"datetime": "2025-07-30 06:45:11 062174 PM", "level": "INFO", "func_name": "__step_run_and_handle_result", "lineno": 272, "filename": "tasks.py", "msg": {"msg:": "__step_run_and_handle_result main try-except after `coro.send()`", "vars": {"task_name": "Custom-task-Task-2"}}}
{"datetime": "2025-07-30 06:45:11 063273 PM", "level": "INFO", "func_name": "__step_run_and_handle_result", "lineno": 310, "filename": "tasks.py", "msg": {"msg": "try-else in __step_run_and_handle_result", "vars": {"task_name": "Custom-task-Task-2", "future_name": null, "result": "None", "is_asyncio_future_blocking": "getattr(result,\"_asyncio_future_blocking\", None)= None"}}}
{"datetime": "2025-07-30 06:45:11 063273 PM", "level": "INFO", "func_name": "__step_run_and_handle_result", "lineno": 313, "filename": "tasks.py", "msg": {"msg": "is_future blocking", "vars": {"task_name": "Custom-task-Task-2", "future_name": null, "is_future_blocking": null}}}
{"datetime": "2025-07-30 06:45:11 064489 PM", "level": "INFO", "func_name": "__step_run_and_handle_result", "lineno": 357, "filename": "tasks.py", "msg": {"msg": "result is None. Scheduling on EVENT_LOOP self.__step", "vars": {"task_name": "Custom-task-Task-2", "future_name": "No future"}}}
{"datetime": "2025-07-30 06:45:11 065571 PM", "level": "INFO", "func_name": "__step_run_and_handle_result", "lineno": 372, "filename": "tasks.py", "msg": {"msg": "self finally set to None", "vars": {"task_name": "Custom-task-Task-2"}}}
{"datetime": "2025-07-30 06:45:11 065571 PM", "level": "INFO", "func_name": "__step", "lineno": 250, "filename": "tasks.py", "msg": {"msg": "`try` of try-finally in `self.__step`. After __step_run_and_handle_result", "vars": {"task_name": "Custom-task-Task-2"}}}
{"datetime": "2025-07-30 06:45:11 066474 PM", "level": "INFO", "func_name": "__step", "lineno": 255, "filename": "tasks.py", "msg": {"msg": "`finally` of try-finally in `self.__step`. Call to _leave_task next and then set self to None", "vars": {"task_name": "Custom-task-Task-2"}}}
{"datetime": "2025-07-30 06:45:11 066474 PM", "level": "INFO", "func_name": "__step", "lineno": 259, "filename": "tasks.py", "msg": {"msg": "`finally` of try-finally in `self.__step`.Custom-task-Task-2 set to none", "vars": {"task_name": "Custom-task-Task-2"}}}
{"datetime": "2025-07-30 06:45:11 067477 PM", "level": "INFO", "func_name": "__wakeup", "lineno": 401, "filename": "tasks.py", "msg": {"msg": "end of __wakeup. set self = None", "vars": {"task_name": "Custom-task-Task-2", "future_name": "Custom-task-Task-2: name: 1"}}}
{"datetime": "2025-07-30 06:45:11 067864 PM", "level": "INFO", "func_name": "__wakeup", "lineno": 377, "filename": "tasks.py", "msg": {"msg": "__wakeup entered", "vars": {"task_name": "Custom-task-Task-3", "future_name": "Custom-task-Task-3: name: 1", "future_state": "FINISHED"}}}
{"datetime": "2025-07-30 06:45:11 067864 PM", "level": "INFO", "func_name": "__wakeup", "lineno": 380, "filename": "tasks.py", "msg": {"msg": "will call future.result()", "vars": {"task_name": "Custom-task-Task-3", "future_name": "Custom-task-Task-3: name: 1"}}}
{"datetime": "2025-07-30 06:45:11 067864 PM", "level": "INFO", "func_name": "__wakeup", "lineno": 382, "filename": "tasks.py", "msg": {"msg": "__wakeup after future.result()", "vars": {"task_name": "Custom-task-Task-3", "future_name": "Custom-task-Task-3: name: 1", "future._state": "FINISHED"}}}
{"datetime": "2025-07-30 06:45:11 067864 PM", "level": "INFO", "func_name": "__wakeup", "lineno": 398, "filename": "tasks.py", "msg": {"msg": "__wakeup faced no exception when it called future.result()(Custom-task-Task-3: name: 1). calling again __step with no exc. I guess StopIteration will be raised", "vars": {"task_name": "Custom-task-Task-3", "future_name": "Custom-task-Task-3: name: 1"}}}
{"datetime": "2025-07-30 06:45:11 067864 PM", "level": "INFO", "func_name": "__step", "lineno": 231, "filename": "tasks.py", "msg": {"msg": "Entered self.__step", "method_signature": "__step(self, exc = None)", "vars": {"task_name": "Custom-task-Task-3", "exc": "None", "sent_from": "'_wakeup._else'"}}}
{"datetime": "2025-07-30 06:45:11 067864 PM", "level": "INFO", "func_name": "__step", "lineno": 241, "filename": "tasks.py", "msg": {"msg": "will initalized self._fut_waiter value", "vars": {"task_name": "Custom-task-Task-3"}}}
{"datetime": "2025-07-30 06:45:11 067864 PM", "level": "INFO", "func_name": "__step", "lineno": 243, "filename": "tasks.py", "msg": {"msg": "initalized self._fut_waiter to None", "vars": {"task_name": "Custom-task-Task-3"}}}
{"datetime": "2025-07-30 06:45:11 067864 PM", "level": "INFO", "func_name": "__step", "lineno": 248, "filename": "tasks.py", "msg": {"msg": "`try` of try-finally in `self.__step`. Call to __step_run_and_handle_request in next line.", "vars": {"task_name": "Custom-task-Task-3"}}}
{"datetime": "2025-07-30 06:45:11 067864 PM", "level": "INFO", "func_name": "__step_run_and_handle_result", "lineno": 262, "filename": "tasks.py", "msg": {"msg": "__step_run_and_handle_request entered", "method_signature": "__step_run_and_handle_result(self, exc)", "vars": {"task_name": "Custom-task-Task-3", "exc": "None"}}}
{"datetime": "2025-07-30 06:45:11 090969 PM", "level": "INFO", "func_name": "__step_run_and_handle_result", "lineno": 269, "filename": "tasks.py", "msg": {"msg": "`__step_run_and_hanle_result` main try-except exc is None so `coro.send()` in next line.", "vars": {"task_name": "Custom-task-Task-3"}}}
{"datetime": "2025-07-30 06:45:11 102987 PM", "level": "INFO", "func_name": "third", "lineno": 31, "filename": "understanding_tasks.py", "msg": "========= SECOND.SECOND ========================="}
{"datetime": "2025-07-30 06:45:11 105494 PM", "level": "INFO", "func_name": "__step_run_and_handle_result", "lineno": 272, "filename": "tasks.py", "msg": {"msg:": "__step_run_and_handle_result main try-except after `coro.send()`", "vars": {"task_name": "Custom-task-Task-3"}}}
{"datetime": "2025-07-30 06:45:11 105494 PM", "level": "INFO", "func_name": "__step_run_and_handle_result", "lineno": 310, "filename": "tasks.py", "msg": {"msg": "try-else in __step_run_and_handle_result", "vars": {"task_name": "Custom-task-Task-3", "future_name": null, "result": "None", "is_asyncio_future_blocking": "getattr(result,\"_asyncio_future_blocking\", None)= None"}}}
{"datetime": "2025-07-30 06:45:11 107502 PM", "level": "INFO", "func_name": "__step_run_and_handle_result", "lineno": 313, "filename": "tasks.py", "msg": {"msg": "is_future blocking", "vars": {"task_name": "Custom-task-Task-3", "future_name": null, "is_future_blocking": null}}}
{"datetime": "2025-07-30 06:45:11 107502 PM", "level": "INFO", "func_name": "__step_run_and_handle_result", "lineno": 357, "filename": "tasks.py", "msg": {"msg": "result is None. Scheduling on EVENT_LOOP self.__step", "vars": {"task_name": "Custom-task-Task-3", "future_name": "No future"}}}
{"datetime": "2025-07-30 06:45:11 114427 PM", "level": "INFO", "func_name": "__step_run_and_handle_result", "lineno": 372, "filename": "tasks.py", "msg": {"msg": "self finally set to None", "vars": {"task_name": "Custom-task-Task-3"}}}
{"datetime": "2025-07-30 06:45:11 118438 PM", "level": "INFO", "func_name": "__step", "lineno": 250, "filename": "tasks.py", "msg": {"msg": "`try` of try-finally in `self.__step`. After __step_run_and_handle_result", "vars": {"task_name": "Custom-task-Task-3"}}}
{"datetime": "2025-07-30 06:45:11 122448 PM", "level": "INFO", "func_name": "__step", "lineno": 255, "filename": "tasks.py", "msg": {"msg": "`finally` of try-finally in `self.__step`. Call to _leave_task next and then set self to None", "vars": {"task_name": "Custom-task-Task-3"}}}
{"datetime": "2025-07-30 06:45:11 130492 PM", "level": "INFO", "func_name": "__step", "lineno": 259, "filename": "tasks.py", "msg": {"msg": "`finally` of try-finally in `self.__step`.Custom-task-Task-3 set to none", "vars": {"task_name": "Custom-task-Task-3"}}}
{"datetime": "2025-07-30 06:45:11 130492 PM", "level": "INFO", "func_name": "__wakeup", "lineno": 401, "filename": "tasks.py", "msg": {"msg": "end of __wakeup. set self = None", "vars": {"task_name": "Custom-task-Task-3", "future_name": "Custom-task-Task-3: name: 1"}}}
{"datetime": "2025-07-30 06:45:11 130492 PM", "level": "INFO", "func_name": "__step", "lineno": 231, "filename": "tasks.py", "msg": {"msg": "Entered self.__step", "method_signature": "__step(self, exc = None)", "vars": {"task_name": "Custom-task-Task-2", "exc": "None", "sent_from": "'__step_run_and_handle_result'"}}}
{"datetime": "2025-07-30 06:45:11 130492 PM", "level": "INFO", "func_name": "__step", "lineno": 241, "filename": "tasks.py", "msg": {"msg": "will initalized self._fut_waiter value", "vars": {"task_name": "Custom-task-Task-2"}}}
{"datetime": "2025-07-30 06:45:11 130492 PM", "level": "INFO", "func_name": "__step", "lineno": 243, "filename": "tasks.py", "msg": {"msg": "initalized self._fut_waiter to None", "vars": {"task_name": "Custom-task-Task-2"}}}
{"datetime": "2025-07-30 06:45:11 130492 PM", "level": "INFO", "func_name": "__step", "lineno": 248, "filename": "tasks.py", "msg": {"msg": "`try` of try-finally in `self.__step`. Call to __step_run_and_handle_request in next line.", "vars": {"task_name": "Custom-task-Task-2"}}}
{"datetime": "2025-07-30 06:45:11 130492 PM", "level": "INFO", "func_name": "__step_run_and_handle_result", "lineno": 262, "filename": "tasks.py", "msg": {"msg": "__step_run_and_handle_request entered", "method_signature": "__step_run_and_handle_result(self, exc)", "vars": {"task_name": "Custom-task-Task-2", "exc": "None"}}}
{"datetime": "2025-07-30 06:45:11 130492 PM", "level": "INFO", "func_name": "__step_run_and_handle_result", "lineno": 269, "filename": "tasks.py", "msg": {"msg": "`__step_run_and_hanle_result` main try-except exc is None so `coro.send()` in next line.", "vars": {"task_name": "Custom-task-Task-2"}}}
{"datetime": "2025-07-30 06:45:11 130492 PM", "level": "INFO", "func_name": "second", "lineno": 24, "filename": "understanding_tasks.py", "msg": "=========================== SECOND.THIRD ================="}
{"datetime": "2025-07-30 06:45:11 130492 PM", "level": "INFO", "func_name": "__step_run_and_handle_result", "lineno": 272, "filename": "tasks.py", "msg": {"msg:": "__step_run_and_handle_result main try-except after `coro.send()`", "vars": {"task_name": "Custom-task-Task-2"}}}
{"datetime": "2025-07-30 06:45:11 130492 PM", "level": "INFO", "func_name": "__step_run_and_handle_result", "lineno": 310, "filename": "tasks.py", "msg": {"msg": "try-else in __step_run_and_handle_result", "vars": {"task_name": "Custom-task-Task-2", "future_name": "Custom-task-Task-2: name: 2", "result": "<Future pending created at C:\\msys64\\mingw64\\lib\\python3.12\\asyncio\\base_events.py:448>", "is_asyncio_future_blocking": "getattr(result,\"_asyncio_future_blocking\", None)= True"}}}
{"datetime": "2025-07-30 06:45:11 130492 PM", "level": "INFO", "func_name": "__step_run_and_handle_result", "lineno": 313, "filename": "tasks.py", "msg": {"msg": "is_future blocking", "vars": {"task_name": "Custom-task-Task-2", "future_name": "Custom-task-Task-2: name: 2", "is_future_blocking": true}}}
{"datetime": "2025-07-30 06:45:11 130492 PM", "level": "INFO", "func_name": "__step_run_and_handle_result", "lineno": 330, "filename": "tasks.py", "msg": {"msg": "scheduling on EVENT_LOOP callback to fututre.add_done_call_back", "vars": {"task_name": "Custom-task-Task-2", "future_name": "Custom-task-Task-2: name: 2", "future_state": "PENDING", "result": "<Future pending created at C:\\msys64\\mingw64\\lib\\python3.12\\asyncio\\base_events.py:448>"}}}
{"datetime": "2025-07-30 06:45:11 130492 PM", "level": "INFO", "func_name": "__step_run_and_handle_result", "lineno": 335, "filename": "tasks.py", "msg": {"msg": "After scheduling callbacks to fut. self._future_wait = result", "vars": {"task_name": "Custom-task-Task-2", "future_name": "Custom-task-Task-2: name: 2", "result": "<Future pending cb=[Task.__wakeup()] created at C:\\msys64\\mingw64\\lib\\python3.12\\asyncio\\base_events.py:448>", "self._fut_waiter": null, "future_state": "PENDING", "future_callbacks_list(fut._callbacks)": "[(<bound method Task.__wakeup of <Task pending name='Custom-task-Task-2' coro=<second() running at c:/Users/shaik/learning/concurrency/python_concurrency/understanding_tasks.py:25> cb=[gather.<locals>._done_callback() at C:\\msys64\\mingw64\\lib\\python3.12\\asyncio\\tasks.py:767] created at c:\\Users\\shaik\\learning\\concurrency\\python_concurrency\\experiments\\tasks.py:410>>, <_contextvars.Context object at 0x00000198acbe6040>)]"}}}
{"datetime": "2025-07-30 06:45:11 130492 PM", "level": "INFO", "func_name": "__step_run_and_handle_result", "lineno": 340, "filename": "tasks.py", "msg": {"msg": "self._fut_waiter set to result", "vars": {"task_name": "Custom-task-Task-2", "future_name": "Custom-task-Task-2: name: 2", "future_state": "PENDING", "self._fut_waiter": "<Future pending cb=[Task.__wakeup()] created at C:\\msys64\\mingw64\\lib\\python3.12\\asyncio\\base_events.py:448>"}}}
{"datetime": "2025-07-30 06:45:11 130492 PM", "level": "INFO", "func_name": "__step_run_and_handle_result", "lineno": 372, "filename": "tasks.py", "msg": {"msg": "self finally set to None", "vars": {"task_name": "Custom-task-Task-2"}}}
{"datetime": "2025-07-30 06:45:11 130492 PM", "level": "INFO", "func_name": "__step", "lineno": 250, "filename": "tasks.py", "msg": {"msg": "`try` of try-finally in `self.__step`. After __step_run_and_handle_result", "vars": {"task_name": "Custom-task-Task-2"}}}
{"datetime": "2025-07-30 06:45:11 130492 PM", "level": "INFO", "func_name": "__step", "lineno": 255, "filename": "tasks.py", "msg": {"msg": "`finally` of try-finally in `self.__step`. Call to _leave_task next and then set self to None", "vars": {"task_name": "Custom-task-Task-2"}}}
{"datetime": "2025-07-30 06:45:11 130492 PM", "level": "INFO", "func_name": "__step", "lineno": 259, "filename": "tasks.py", "msg": {"msg": "`finally` of try-finally in `self.__step`.Custom-task-Task-2 set to none", "vars": {"task_name": "Custom-task-Task-2"}}}
{"datetime": "2025-07-30 06:45:11 130492 PM", "level": "INFO", "func_name": "__step", "lineno": 231, "filename": "tasks.py", "msg": {"msg": "Entered self.__step", "method_signature": "__step(self, exc = None)", "vars": {"task_name": "Custom-task-Task-3", "exc": "None", "sent_from": "'__step_run_and_handle_result'"}}}
{"datetime": "2025-07-30 06:45:11 130492 PM", "level": "INFO", "func_name": "__step", "lineno": 241, "filename": "tasks.py", "msg": {"msg": "will initalized self._fut_waiter value", "vars": {"task_name": "Custom-task-Task-3"}}}
{"datetime": "2025-07-30 06:45:11 130492 PM", "level": "INFO", "func_name": "__step", "lineno": 243, "filename": "tasks.py", "msg": {"msg": "initalized self._fut_waiter to None", "vars": {"task_name": "Custom-task-Task-3"}}}
{"datetime": "2025-07-30 06:45:11 130492 PM", "level": "INFO", "func_name": "__step", "lineno": 248, "filename": "tasks.py", "msg": {"msg": "`try` of try-finally in `self.__step`. Call to __step_run_and_handle_request in next line.", "vars": {"task_name": "Custom-task-Task-3"}}}
{"datetime": "2025-07-30 06:45:11 130492 PM", "level": "INFO", "func_name": "__step_run_and_handle_result", "lineno": 262, "filename": "tasks.py", "msg": {"msg": "__step_run_and_handle_request entered", "method_signature": "__step_run_and_handle_result(self, exc)", "vars": {"task_name": "Custom-task-Task-3", "exc": "None"}}}
{"datetime": "2025-07-30 06:45:11 130492 PM", "level": "INFO", "func_name": "__step_run_and_handle_result", "lineno": 269, "filename": "tasks.py", "msg": {"msg": "`__step_run_and_hanle_result` main try-except exc is None so `coro.send()` in next line.", "vars": {"task_name": "Custom-task-Task-3"}}}
{"datetime": "2025-07-30 06:45:11 153889 PM", "level": "INFO", "func_name": "third", "lineno": 33, "filename": "understanding_tasks.py", "msg": "=========================== SECOND.THIRD ================="}
{"datetime": "2025-07-30 06:45:11 155902 PM", "level": "INFO", "func_name": "__step_run_and_handle_result", "lineno": 272, "filename": "tasks.py", "msg": {"msg:": "__step_run_and_handle_result main try-except after `coro.send()`", "vars": {"task_name": "Custom-task-Task-3"}}}
{"datetime": "2025-07-30 06:45:11 155902 PM", "level": "INFO", "func_name": "__step_run_and_handle_result", "lineno": 310, "filename": "tasks.py", "msg": {"msg": "try-else in __step_run_and_handle_result", "vars": {"task_name": "Custom-task-Task-3", "future_name": "Custom-task-Task-3: name: 2", "result": "<Future pending created at C:\\msys64\\mingw64\\lib\\python3.12\\asyncio\\base_events.py:448>", "is_asyncio_future_blocking": "getattr(result,\"_asyncio_future_blocking\", None)= True"}}}
{"datetime": "2025-07-30 06:45:11 155902 PM", "level": "INFO", "func_name": "__step_run_and_handle_result", "lineno": 313, "filename": "tasks.py", "msg": {"msg": "is_future blocking", "vars": {"task_name": "Custom-task-Task-3", "future_name": "Custom-task-Task-3: name: 2", "is_future_blocking": true}}}
{"datetime": "2025-07-30 06:45:11 155902 PM", "level": "INFO", "func_name": "__step_run_and_handle_result", "lineno": 330, "filename": "tasks.py", "msg": {"msg": "scheduling on EVENT_LOOP callback to fututre.add_done_call_back", "vars": {"task_name": "Custom-task-Task-3", "future_name": "Custom-task-Task-3: name: 2", "future_state": "PENDING", "result": "<Future pending created at C:\\msys64\\mingw64\\lib\\python3.12\\asyncio\\base_events.py:448>"}}}
{"datetime": "2025-07-30 06:45:11 155902 PM", "level": "INFO", "func_name": "__step_run_and_handle_result", "lineno": 335, "filename": "tasks.py", "msg": {"msg": "After scheduling callbacks to fut. self._future_wait = result", "vars": {"task_name": "Custom-task-Task-3", "future_name": "Custom-task-Task-3: name: 2", "result": "<Future pending cb=[Task.__wakeup()] created at C:\\msys64\\mingw64\\lib\\python3.12\\asyncio\\base_events.py:448>", "self._fut_waiter": null, "future_state": "PENDING", "future_callbacks_list(fut._callbacks)": "[(<bound method Task.__wakeup of <Task pending name='Custom-task-Task-3' coro=<third() running at c:/Users/shaik/learning/concurrency/python_concurrency/understanding_tasks.py:34> cb=[gather.<locals>._done_callback() at C:\\msys64\\mingw64\\lib\\python3.12\\asyncio\\tasks.py:767] created at c:\\Users\\shaik\\learning\\concurrency\\python_concurrency\\experiments\\tasks.py:410>>, <_contextvars.Context object at 0x00000198acbe63c0>)]"}}}
{"datetime": "2025-07-30 06:45:11 155902 PM", "level": "INFO", "func_name": "__step_run_and_handle_result", "lineno": 340, "filename": "tasks.py", "msg": {"msg": "self._fut_waiter set to result", "vars": {"task_name": "Custom-task-Task-3", "future_name": "Custom-task-Task-3: name: 2", "future_state": "PENDING", "self._fut_waiter": "<Future pending cb=[Task.__wakeup()] created at C:\\msys64\\mingw64\\lib\\python3.12\\asyncio\\base_events.py:448>"}}}
{"datetime": "2025-07-30 06:45:11 160967 PM", "level": "INFO", "func_name": "__step_run_and_handle_result", "lineno": 372, "filename": "tasks.py", "msg": {"msg": "self finally set to None", "vars": {"task_name": "Custom-task-Task-3"}}}
{"datetime": "2025-07-30 06:45:11 160967 PM", "level": "INFO", "func_name": "__step", "lineno": 250, "filename": "tasks.py", "msg": {"msg": "`try` of try-finally in `self.__step`. After __step_run_and_handle_result", "vars": {"task_name": "Custom-task-Task-3"}}}
{"datetime": "2025-07-30 06:45:11 160967 PM", "level": "INFO", "func_name": "__step", "lineno": 255, "filename": "tasks.py", "msg": {"msg": "`finally` of try-finally in `self.__step`. Call to _leave_task next and then set self to None", "vars": {"task_name": "Custom-task-Task-3"}}}
{"datetime": "2025-07-30 06:45:11 161967 PM", "level": "INFO", "func_name": "__step", "lineno": 259, "filename": "tasks.py", "msg": {"msg": "`finally` of try-finally in `self.__step`.Custom-task-Task-3 set to none", "vars": {"task_name": "Custom-task-Task-3"}}}
{"datetime": "2025-07-30 06:45:11 247625 PM", "level": "INFO", "func_name": "__wakeup", "lineno": 377, "filename": "tasks.py", "msg": {"msg": "__wakeup entered", "vars": {"task_name": "Custom-task-Task-2", "future_name": "Custom-task-Task-2: name: 2", "future_state": "FINISHED"}}}
{"datetime": "2025-07-30 06:45:11 247625 PM", "level": "INFO", "func_name": "__wakeup", "lineno": 380, "filename": "tasks.py", "msg": {"msg": "will call future.result()", "vars": {"task_name": "Custom-task-Task-2", "future_name": "Custom-task-Task-2: name: 2"}}}
{"datetime": "2025-07-30 06:45:11 247625 PM", "level": "INFO", "func_name": "__wakeup", "lineno": 382, "filename": "tasks.py", "msg": {"msg": "__wakeup after future.result()", "vars": {"task_name": "Custom-task-Task-2", "future_name": "Custom-task-Task-2: name: 2", "future._state": "FINISHED"}}}
{"datetime": "2025-07-30 06:45:11 247625 PM", "level": "INFO", "func_name": "__wakeup", "lineno": 398, "filename": "tasks.py", "msg": {"msg": "__wakeup faced no exception when it called future.result()(Custom-task-Task-2: name: 2). calling again __step with no exc. I guess StopIteration will be raised", "vars": {"task_name": "Custom-task-Task-2", "future_name": "Custom-task-Task-2: name: 2"}}}
{"datetime": "2025-07-30 06:45:11 247625 PM", "level": "INFO", "func_name": "__step", "lineno": 231, "filename": "tasks.py", "msg": {"msg": "Entered self.__step", "method_signature": "__step(self, exc = None)", "vars": {"task_name": "Custom-task-Task-2", "exc": "None", "sent_from": "'_wakeup._else'"}}}
{"datetime": "2025-07-30 06:45:11 247625 PM", "level": "INFO", "func_name": "__step", "lineno": 241, "filename": "tasks.py", "msg": {"msg": "will initalized self._fut_waiter value", "vars": {"task_name": "Custom-task-Task-2"}}}
{"datetime": "2025-07-30 06:45:11 247625 PM", "level": "INFO", "func_name": "__step", "lineno": 243, "filename": "tasks.py", "msg": {"msg": "initalized self._fut_waiter to None", "vars": {"task_name": "Custom-task-Task-2"}}}
{"datetime": "2025-07-30 06:45:11 247625 PM", "level": "INFO", "func_name": "__step", "lineno": 248, "filename": "tasks.py", "msg": {"msg": "`try` of try-finally in `self.__step`. Call to __step_run_and_handle_request in next line.", "vars": {"task_name": "Custom-task-Task-2"}}}
{"datetime": "2025-07-30 06:45:11 257577 PM", "level": "INFO", "func_name": "__step_run_and_handle_result", "lineno": 262, "filename": "tasks.py", "msg": {"msg": "__step_run_and_handle_request entered", "method_signature": "__step_run_and_handle_result(self, exc)", "vars": {"task_name": "Custom-task-Task-2", "exc": "None"}}}
{"datetime": "2025-07-30 06:45:11 258758 PM", "level": "INFO", "func_name": "__step_run_and_handle_result", "lineno": 269, "filename": "tasks.py", "msg": {"msg": "`__step_run_and_hanle_result` main try-except exc is None so `coro.send()` in next line.", "vars": {"task_name": "Custom-task-Task-2"}}}
{"datetime": "2025-07-30 06:45:11 259753 PM", "level": "INFO", "func_name": "second", "lineno": 26, "filename": "understanding_tasks.py", "msg": "========== END ==========="}
{"datetime": "2025-07-30 06:45:11 260765 PM", "level": "INFO", "func_name": "__step_run_and_handle_result", "lineno": 282, "filename": "tasks.py", "msg": {"msg": "StopIteration exception encountered.", "vars": {"task_name": "Custom-task-Task-2", "future_name": "NO_AWAITABLE"}}}
{"datetime": "2025-07-30 06:45:11 262080 PM", "level": "INFO", "func_name": "__step_run_and_handle_result", "lineno": 291, "filename": "tasks.py", "msg": {"msg": "__step_run_and_handle_result StopIteration encountered but the task is not cancelled.", "vars": {"task_name": "Custom-task-Task-2", "exc.value": "None"}}}
{"datetime": "2025-07-30 06:45:11 265103 PM", "level": "INFO", "func_name": "__step_run_and_handle_result", "lineno": 294, "filename": "tasks.py", "msg": {"msg": "super().set_result(exc.value)", "vars": {"task_name": "Custom-task-Task-2"}}}
{"datetime": "2025-07-30 06:45:11 266106 PM", "level": "INFO", "func_name": "__step_run_and_handle_result", "lineno": 372, "filename": "tasks.py", "msg": {"msg": "self finally set to None", "vars": {"task_name": "Custom-task-Task-2"}}}
{"datetime": "2025-07-30 06:45:11 268997 PM", "level": "INFO", "func_name": "__step", "lineno": 250, "filename": "tasks.py", "msg": {"msg": "`try` of try-finally in `self.__step`. After __step_run_and_handle_result", "vars": {"task_name": "Custom-task-Task-2"}}}
{"datetime": "2025-07-30 06:45:11 270582 PM", "level": "INFO", "func_name": "__step", "lineno": 255, "filename": "tasks.py", "msg": {"msg": "`finally` of try-finally in `self.__step`. Call to _leave_task next and then set self to None", "vars": {"task_name": "Custom-task-Task-2"}}}
{"datetime": "2025-07-30 06:45:11 271580 PM", "level": "INFO", "func_name": "__step", "lineno": 259, "filename": "tasks.py", "msg": {"msg": "`finally` of try-finally in `self.__step`.Custom-task-Task-2 set to none", "vars": {"task_name": "Custom-task-Task-2"}}}
{"datetime": "2025-07-30 06:45:11 272577 PM", "level": "INFO", "func_name": "__wakeup", "lineno": 401, "filename": "tasks.py", "msg": {"msg": "end of __wakeup. set self = None", "vars": {"task_name": "Custom-task-Task-2", "future_name": "Custom-task-Task-2: name: 2"}}}
{"datetime": "2025-07-30 06:45:11 274580 PM", "level": "INFO", "func_name": "__wakeup", "lineno": 377, "filename": "tasks.py", "msg": {"msg": "__wakeup entered", "vars": {"task_name": "Custom-task-Task-3", "future_name": "Custom-task-Task-3: name: 2", "future_state": "FINISHED"}}}
{"datetime": "2025-07-30 06:45:11 275802 PM", "level": "INFO", "func_name": "__wakeup", "lineno": 380, "filename": "tasks.py", "msg": {"msg": "will call future.result()", "vars": {"task_name": "Custom-task-Task-3", "future_name": "Custom-task-Task-3: name: 2"}}}
{"datetime": "2025-07-30 06:45:11 275802 PM", "level": "INFO", "func_name": "__wakeup", "lineno": 382, "filename": "tasks.py", "msg": {"msg": "__wakeup after future.result()", "vars": {"task_name": "Custom-task-Task-3", "future_name": "Custom-task-Task-3: name: 2", "future._state": "FINISHED"}}}
{"datetime": "2025-07-30 06:45:11 277721 PM", "level": "INFO", "func_name": "__wakeup", "lineno": 398, "filename": "tasks.py", "msg": {"msg": "__wakeup faced no exception when it called future.result()(Custom-task-Task-3: name: 2). calling again __step with no exc. I guess StopIteration will be raised", "vars": {"task_name": "Custom-task-Task-3", "future_name": "Custom-task-Task-3: name: 2"}}}
{"datetime": "2025-07-30 06:45:11 278736 PM", "level": "INFO", "func_name": "__step", "lineno": 231, "filename": "tasks.py", "msg": {"msg": "Entered self.__step", "method_signature": "__step(self, exc = None)", "vars": {"task_name": "Custom-task-Task-3", "exc": "None", "sent_from": "'_wakeup._else'"}}}
{"datetime": "2025-07-30 06:45:11 279743 PM", "level": "INFO", "func_name": "__step", "lineno": 241, "filename": "tasks.py", "msg": {"msg": "will initalized self._fut_waiter value", "vars": {"task_name": "Custom-task-Task-3"}}}
{"datetime": "2025-07-30 06:45:11 280742 PM", "level": "INFO", "func_name": "__step", "lineno": 243, "filename": "tasks.py", "msg": {"msg": "initalized self._fut_waiter to None", "vars": {"task_name": "Custom-task-Task-3"}}}
{"datetime": "2025-07-30 06:45:11 281734 PM", "level": "INFO", "func_name": "__step", "lineno": 248, "filename": "tasks.py", "msg": {"msg": "`try` of try-finally in `self.__step`. Call to __step_run_and_handle_request in next line.", "vars": {"task_name": "Custom-task-Task-3"}}}
{"datetime": "2025-07-30 06:45:11 282732 PM", "level": "INFO", "func_name": "__step_run_and_handle_result", "lineno": 262, "filename": "tasks.py", "msg": {"msg": "__step_run_and_handle_request entered", "method_signature": "__step_run_and_handle_result(self, exc)", "vars": {"task_name": "Custom-task-Task-3", "exc": "None"}}}
{"datetime": "2025-07-30 06:45:11 284768 PM", "level": "INFO", "func_name": "__step_run_and_handle_result", "lineno": 269, "filename": "tasks.py", "msg": {"msg": "`__step_run_and_hanle_result` main try-except exc is None so `coro.send()` in next line.", "vars": {"task_name": "Custom-task-Task-3"}}}
{"datetime": "2025-07-30 06:45:11 285218 PM", "level": "INFO", "func_name": "third", "lineno": 35, "filename": "understanding_tasks.py", "msg": "========== END ==========="}
{"datetime": "2025-07-30 06:45:11 286324 PM", "level": "INFO", "func_name": "__step_run_and_handle_result", "lineno": 282, "filename": "tasks.py", "msg": {"msg": "StopIteration exception encountered.", "vars": {"task_name": "Custom-task-Task-3", "future_name": "NO_AWAITABLE"}}}
{"datetime": "2025-07-30 06:45:11 287321 PM", "level": "INFO", "func_name": "__step_run_and_handle_result", "lineno": 291, "filename": "tasks.py", "msg": {"msg": "__step_run_and_handle_result StopIteration encountered but the task is not cancelled.", "vars": {"task_name": "Custom-task-Task-3", "exc.value": "None"}}}
{"datetime": "2025-07-30 06:45:11 288133 PM", "level": "INFO", "func_name": "__step_run_and_handle_result", "lineno": 294, "filename": "tasks.py", "msg": {"msg": "super().set_result(exc.value)", "vars": {"task_name": "Custom-task-Task-3"}}}
{"datetime": "2025-07-30 06:45:11 289141 PM", "level": "INFO", "func_name": "__step_run_and_handle_result", "lineno": 372, "filename": "tasks.py", "msg": {"msg": "self finally set to None", "vars": {"task_name": "Custom-task-Task-3"}}}
{"datetime": "2025-07-30 06:45:11 290141 PM", "level": "INFO", "func_name": "__step", "lineno": 250, "filename": "tasks.py", "msg": {"msg": "`try` of try-finally in `self.__step`. After __step_run_and_handle_result", "vars": {"task_name": "Custom-task-Task-3"}}}
{"datetime": "2025-07-30 06:45:11 290141 PM", "level": "INFO", "func_name": "__step", "lineno": 255, "filename": "tasks.py", "msg": {"msg": "`finally` of try-finally in `self.__step`. Call to _leave_task next and then set self to None", "vars": {"task_name": "Custom-task-Task-3"}}}
{"datetime": "2025-07-30 06:45:11 290141 PM", "level": "INFO", "func_name": "__step", "lineno": 259, "filename": "tasks.py", "msg": {"msg": "`finally` of try-finally in `self.__step`.Custom-task-Task-3 set to none", "vars": {"task_name": "Custom-task-Task-3"}}}
{"datetime": "2025-07-30 06:45:11 290141 PM", "level": "INFO", "func_name": "__wakeup", "lineno": 401, "filename": "tasks.py", "msg": {"msg": "end of __wakeup. set self = None", "vars": {"task_name": "Custom-task-Task-3", "future_name": "Custom-task-Task-3: name: 2"}}}
{"datetime": "2025-07-30 06:45:14 529841 PM", "level": "INFO", "func_name": "__wakeup", "lineno": 377, "filename": "tasks.py", "msg": {"msg": "__wakeup entered", "vars": {"task_name": "Custom-task-Task-1", "future_name": "Custom-task-Task-1: name: 1", "future_state": "FINISHED"}}}
{"datetime": "2025-07-30 06:45:14 531003 PM", "level": "INFO", "func_name": "__wakeup", "lineno": 380, "filename": "tasks.py", "msg": {"msg": "will call future.result()", "vars": {"task_name": "Custom-task-Task-1", "future_name": "Custom-task-Task-1: name: 1"}}}
{"datetime": "2025-07-30 06:45:14 531003 PM", "level": "INFO", "func_name": "__wakeup", "lineno": 382, "filename": "tasks.py", "msg": {"msg": "__wakeup after future.result()", "vars": {"task_name": "Custom-task-Task-1", "future_name": "Custom-task-Task-1: name: 1", "future._state": "FINISHED"}}}
{"datetime": "2025-07-30 06:45:14 531915 PM", "level": "INFO", "func_name": "__wakeup", "lineno": 398, "filename": "tasks.py", "msg": {"msg": "__wakeup faced no exception when it called future.result()(Custom-task-Task-1: name: 1). calling again __step with no exc. I guess StopIteration will be raised", "vars": {"task_name": "Custom-task-Task-1", "future_name": "Custom-task-Task-1: name: 1"}}}
{"datetime": "2025-07-30 06:45:14 531915 PM", "level": "INFO", "func_name": "__step", "lineno": 231, "filename": "tasks.py", "msg": {"msg": "Entered self.__step", "method_signature": "__step(self, exc = None)", "vars": {"task_name": "Custom-task-Task-1", "exc": "None", "sent_from": "'_wakeup._else'"}}}
{"datetime": "2025-07-30 06:45:14 532917 PM", "level": "INFO", "func_name": "__step", "lineno": 241, "filename": "tasks.py", "msg": {"msg": "will initalized self._fut_waiter value", "vars": {"task_name": "Custom-task-Task-1"}}}
{"datetime": "2025-07-30 06:45:14 532917 PM", "level": "INFO", "func_name": "__step", "lineno": 243, "filename": "tasks.py", "msg": {"msg": "initalized self._fut_waiter to None", "vars": {"task_name": "Custom-task-Task-1"}}}
{"datetime": "2025-07-30 06:45:14 533622 PM", "level": "INFO", "func_name": "__step", "lineno": 248, "filename": "tasks.py", "msg": {"msg": "`try` of try-finally in `self.__step`. Call to __step_run_and_handle_request in next line.", "vars": {"task_name": "Custom-task-Task-1"}}}
{"datetime": "2025-07-30 06:45:14 533622 PM", "level": "INFO", "func_name": "__step_run_and_handle_result", "lineno": 262, "filename": "tasks.py", "msg": {"msg": "__step_run_and_handle_request entered", "method_signature": "__step_run_and_handle_result(self, exc)", "vars": {"task_name": "Custom-task-Task-1", "exc": "None"}}}
{"datetime": "2025-07-30 06:45:14 534709 PM", "level": "INFO", "func_name": "__step_run_and_handle_result", "lineno": 269, "filename": "tasks.py", "msg": {"msg": "`__step_run_and_hanle_result` main try-except exc is None so `coro.send()` in next line.", "vars": {"task_name": "Custom-task-Task-1"}}}
{"datetime": "2025-07-30 06:45:14 535712 PM", "level": "INFO", "func_name": "first", "lineno": 13, "filename": "understanding_tasks.py", "msg": "========= FIRST.SECOND ========================="}
{"datetime": "2025-07-30 06:45:14 537362 PM", "level": "INFO", "func_name": "__step_run_and_handle_result", "lineno": 272, "filename": "tasks.py", "msg": {"msg:": "__step_run_and_handle_result main try-except after `coro.send()`", "vars": {"task_name": "Custom-task-Task-1"}}}
{"datetime": "2025-07-30 06:45:14 537362 PM", "level": "INFO", "func_name": "__step_run_and_handle_result", "lineno": 310, "filename": "tasks.py", "msg": {"msg": "try-else in __step_run_and_handle_result", "vars": {"task_name": "Custom-task-Task-1", "future_name": "Custom-task-Task-1: name: 2", "result": "<Future pending created at C:\\msys64\\mingw64\\lib\\python3.12\\asyncio\\base_events.py:448>", "is_asyncio_future_blocking": "getattr(result,\"_asyncio_future_blocking\", None)= True"}}}
{"datetime": "2025-07-30 06:45:14 538367 PM", "level": "INFO", "func_name": "__step_run_and_handle_result", "lineno": 313, "filename": "tasks.py", "msg": {"msg": "is_future blocking", "vars": {"task_name": "Custom-task-Task-1", "future_name": "Custom-task-Task-1: name: 2", "is_future_blocking": true}}}
{"datetime": "2025-07-30 06:45:14 538718 PM", "level": "INFO", "func_name": "__step_run_and_handle_result", "lineno": 330, "filename": "tasks.py", "msg": {"msg": "scheduling on EVENT_LOOP callback to fututre.add_done_call_back", "vars": {"task_name": "Custom-task-Task-1", "future_name": "Custom-task-Task-1: name: 2", "future_state": "PENDING", "result": "<Future pending created at C:\\msys64\\mingw64\\lib\\python3.12\\asyncio\\base_events.py:448>"}}}
{"datetime": "2025-07-30 06:45:14 539160 PM", "level": "INFO", "func_name": "__step_run_and_handle_result", "lineno": 335, "filename": "tasks.py", "msg": {"msg": "After scheduling callbacks to fut. self._future_wait = result", "vars": {"task_name": "Custom-task-Task-1", "future_name": "Custom-task-Task-1: name: 2", "result": "<Future pending cb=[Task.__wakeup()] created at C:\\msys64\\mingw64\\lib\\python3.12\\asyncio\\base_events.py:448>", "self._fut_waiter": null, "future_state": "PENDING", "future_callbacks_list(fut._callbacks)": "[(<bound method Task.__wakeup of <Task pending name='Custom-task-Task-1' coro=<first() running at c:/Users/shaik/learning/concurrency/python_concurrency/understanding_tasks.py:14> cb=[gather.<locals>._done_callback() at C:\\msys64\\mingw64\\lib\\python3.12\\asyncio\\tasks.py:767] created at c:\\Users\\shaik\\learning\\concurrency\\python_concurrency\\experiments\\tasks.py:410>>, <_contextvars.Context object at 0x00000198ac24b5c0>)]"}}}
{"datetime": "2025-07-30 06:45:14 539160 PM", "level": "INFO", "func_name": "__step_run_and_handle_result", "lineno": 340, "filename": "tasks.py", "msg": {"msg": "self._fut_waiter set to result", "vars": {"task_name": "Custom-task-Task-1", "future_name": "Custom-task-Task-1: name: 2", "future_state": "PENDING", "self._fut_waiter": "<Future pending cb=[Task.__wakeup()] created at C:\\msys64\\mingw64\\lib\\python3.12\\asyncio\\base_events.py:448>"}}}
{"datetime": "2025-07-30 06:45:14 540213 PM", "level": "INFO", "func_name": "__step_run_and_handle_result", "lineno": 372, "filename": "tasks.py", "msg": {"msg": "self finally set to None", "vars": {"task_name": "Custom-task-Task-1"}}}
{"datetime": "2025-07-30 06:45:14 540213 PM", "level": "INFO", "func_name": "__step", "lineno": 250, "filename": "tasks.py", "msg": {"msg": "`try` of try-finally in `self.__step`. After __step_run_and_handle_result", "vars": {"task_name": "Custom-task-Task-1"}}}
{"datetime": "2025-07-30 06:45:14 540693 PM", "level": "INFO", "func_name": "__step", "lineno": 255, "filename": "tasks.py", "msg": {"msg": "`finally` of try-finally in `self.__step`. Call to _leave_task next and then set self to None", "vars": {"task_name": "Custom-task-Task-1"}}}
{"datetime": "2025-07-30 06:45:14 541377 PM", "level": "INFO", "func_name": "__step", "lineno": 259, "filename": "tasks.py", "msg": {"msg": "`finally` of try-finally in `self.__step`.Custom-task-Task-1 set to none", "vars": {"task_name": "Custom-task-Task-1"}}}
{"datetime": "2025-07-30 06:45:14 541377 PM", "level": "INFO", "func_name": "__wakeup", "lineno": 401, "filename": "tasks.py", "msg": {"msg": "end of __wakeup. set self = None", "vars": {"task_name": "Custom-task-Task-1", "future_name": "Custom-task-Task-1: name: 1"}}}
{"datetime": "2025-07-30 06:45:14 851248 PM", "level": "INFO", "func_name": "__wakeup", "lineno": 377, "filename": "tasks.py", "msg": {"msg": "__wakeup entered", "vars": {"task_name": "Custom-task-Task-1", "future_name": "Custom-task-Task-1: name: 2", "future_state": "FINISHED"}}}
{"datetime": "2025-07-30 06:45:14 851828 PM", "level": "INFO", "func_name": "__wakeup", "lineno": 380, "filename": "tasks.py", "msg": {"msg": "will call future.result()", "vars": {"task_name": "Custom-task-Task-1", "future_name": "Custom-task-Task-1: name: 2"}}}
{"datetime": "2025-07-30 06:45:14 852386 PM", "level": "INFO", "func_name": "__wakeup", "lineno": 382, "filename": "tasks.py", "msg": {"msg": "__wakeup after future.result()", "vars": {"task_name": "Custom-task-Task-1", "future_name": "Custom-task-Task-1: name: 2", "future._state": "FINISHED"}}}
{"datetime": "2025-07-30 06:45:14 853047 PM", "level": "INFO", "func_name": "__wakeup", "lineno": 398, "filename": "tasks.py", "msg": {"msg": "__wakeup faced no exception when it called future.result()(Custom-task-Task-1: name: 2). calling again __step with no exc. I guess StopIteration will be raised", "vars": {"task_name": "Custom-task-Task-1", "future_name": "Custom-task-Task-1: name: 2"}}}
{"datetime": "2025-07-30 06:45:14 853047 PM", "level": "INFO", "func_name": "__step", "lineno": 231, "filename": "tasks.py", "msg": {"msg": "Entered self.__step", "method_signature": "__step(self, exc = None)", "vars": {"task_name": "Custom-task-Task-1", "exc": "None", "sent_from": "'_wakeup._else'"}}}
{"datetime": "2025-07-30 06:45:14 854070 PM", "level": "INFO", "func_name": "__step", "lineno": 241, "filename": "tasks.py", "msg": {"msg": "will initalized self._fut_waiter value", "vars": {"task_name": "Custom-task-Task-1"}}}
{"datetime": "2025-07-30 06:45:14 854070 PM", "level": "INFO", "func_name": "__step", "lineno": 243, "filename": "tasks.py", "msg": {"msg": "initalized self._fut_waiter to None", "vars": {"task_name": "Custom-task-Task-1"}}}
{"datetime": "2025-07-30 06:45:14 855054 PM", "level": "INFO", "func_name": "__step", "lineno": 248, "filename": "tasks.py", "msg": {"msg": "`try` of try-finally in `self.__step`. Call to __step_run_and_handle_request in next line.", "vars": {"task_name": "Custom-task-Task-1"}}}
{"datetime": "2025-07-30 06:45:14 855054 PM", "level": "INFO", "func_name": "__step_run_and_handle_result", "lineno": 262, "filename": "tasks.py", "msg": {"msg": "__step_run_and_handle_request entered", "method_signature": "__step_run_and_handle_result(self, exc)", "vars": {"task_name": "Custom-task-Task-1", "exc": "None"}}}
{"datetime": "2025-07-30 06:45:14 856056 PM", "level": "INFO", "func_name": "__step_run_and_handle_result", "lineno": 269, "filename": "tasks.py", "msg": {"msg": "`__step_run_and_hanle_result` main try-except exc is None so `coro.send()` in next line.", "vars": {"task_name": "Custom-task-Task-1"}}}
{"datetime": "2025-07-30 06:45:14 856056 PM", "level": "INFO", "func_name": "first", "lineno": 15, "filename": "understanding_tasks.py", "msg": "=========================== FIRST.THIRD ================="}
{"datetime": "2025-07-30 06:45:14 857743 PM", "level": "INFO", "func_name": "__step_run_and_handle_result", "lineno": 272, "filename": "tasks.py", "msg": {"msg:": "__step_run_and_handle_result main try-except after `coro.send()`", "vars": {"task_name": "Custom-task-Task-1"}}}
{"datetime": "2025-07-30 06:45:14 858750 PM", "level": "INFO", "func_name": "__step_run_and_handle_result", "lineno": 310, "filename": "tasks.py", "msg": {"msg": "try-else in __step_run_and_handle_result", "vars": {"task_name": "Custom-task-Task-1", "future_name": "Custom-task-Task-1: name: 3", "result": "<Future pending created at C:\\msys64\\mingw64\\lib\\python3.12\\asyncio\\base_events.py:448>", "is_asyncio_future_blocking": "getattr(result,\"_asyncio_future_blocking\", None)= True"}}}
{"datetime": "2025-07-30 06:45:14 858750 PM", "level": "INFO", "func_name": "__step_run_and_handle_result", "lineno": 313, "filename": "tasks.py", "msg": {"msg": "is_future blocking", "vars": {"task_name": "Custom-task-Task-1", "future_name": "Custom-task-Task-1: name: 3", "is_future_blocking": true}}}
{"datetime": "2025-07-30 06:45:14 859749 PM", "level": "INFO", "func_name": "__step_run_and_handle_result", "lineno": 330, "filename": "tasks.py", "msg": {"msg": "scheduling on EVENT_LOOP callback to fututre.add_done_call_back", "vars": {"task_name": "Custom-task-Task-1", "future_name": "Custom-task-Task-1: name: 3", "future_state": "PENDING", "result": "<Future pending created at C:\\msys64\\mingw64\\lib\\python3.12\\asyncio\\base_events.py:448>"}}}
{"datetime": "2025-07-30 06:45:14 859749 PM", "level": "INFO", "func_name": "__step_run_and_handle_result", "lineno": 335, "filename": "tasks.py", "msg": {"msg": "After scheduling callbacks to fut. self._future_wait = result", "vars": {"task_name": "Custom-task-Task-1", "future_name": "Custom-task-Task-1: name: 3", "result": "<Future pending cb=[Task.__wakeup()] created at C:\\msys64\\mingw64\\lib\\python3.12\\asyncio\\base_events.py:448>", "self._fut_waiter": null, "future_state": "PENDING", "future_callbacks_list(fut._callbacks)": "[(<bound method Task.__wakeup of <Task pending name='Custom-task-Task-1' coro=<first() running at c:/Users/shaik/learning/concurrency/python_concurrency/understanding_tasks.py:16> cb=[gather.<locals>._done_callback() at C:\\msys64\\mingw64\\lib\\python3.12\\asyncio\\tasks.py:767] created at c:\\Users\\shaik\\learning\\concurrency\\python_concurrency\\experiments\\tasks.py:410>>, <_contextvars.Context object at 0x00000198ac24b5c0>)]"}}}
{"datetime": "2025-07-30 06:45:14 860748 PM", "level": "INFO", "func_name": "__step_run_and_handle_result", "lineno": 340, "filename": "tasks.py", "msg": {"msg": "self._fut_waiter set to result", "vars": {"task_name": "Custom-task-Task-1", "future_name": "Custom-task-Task-1: name: 3", "future_state": "PENDING", "self._fut_waiter": "<Future pending cb=[Task.__wakeup()] created at C:\\msys64\\mingw64\\lib\\python3.12\\asyncio\\base_events.py:448>"}}}
{"datetime": "2025-07-30 06:45:14 860748 PM", "level": "INFO", "func_name": "__step_run_and_handle_result", "lineno": 372, "filename": "tasks.py", "msg": {"msg": "self finally set to None", "vars": {"task_name": "Custom-task-Task-1"}}}
{"datetime": "2025-07-30 06:45:14 861748 PM", "level": "INFO", "func_name": "__step", "lineno": 250, "filename": "tasks.py", "msg": {"msg": "`try` of try-finally in `self.__step`. After __step_run_and_handle_result", "vars": {"task_name": "Custom-task-Task-1"}}}
{"datetime": "2025-07-30 06:45:14 861748 PM", "level": "INFO", "func_name": "__step", "lineno": 255, "filename": "tasks.py", "msg": {"msg": "`finally` of try-finally in `self.__step`. Call to _leave_task next and then set self to None", "vars": {"task_name": "Custom-task-Task-1"}}}
{"datetime": "2025-07-30 06:45:14 861748 PM", "level": "INFO", "func_name": "__step", "lineno": 259, "filename": "tasks.py", "msg": {"msg": "`finally` of try-finally in `self.__step`.Custom-task-Task-1 set to none", "vars": {"task_name": "Custom-task-Task-1"}}}
{"datetime": "2025-07-30 06:45:14 862754 PM", "level": "INFO", "func_name": "__wakeup", "lineno": 401, "filename": "tasks.py", "msg": {"msg": "end of __wakeup. set self = None", "vars": {"task_name": "Custom-task-Task-1", "future_name": "Custom-task-Task-1: name: 2"}}}
{"datetime": "2025-07-30 06:45:14 949353 PM", "level": "INFO", "func_name": "__wakeup", "lineno": 377, "filename": "tasks.py", "msg": {"msg": "__wakeup entered", "vars": {"task_name": "Custom-task-Task-1", "future_name": "Custom-task-Task-1: name: 3", "future_state": "FINISHED"}}}
{"datetime": "2025-07-30 06:45:14 949353 PM", "level": "INFO", "func_name": "__wakeup", "lineno": 380, "filename": "tasks.py", "msg": {"msg": "will call future.result()", "vars": {"task_name": "Custom-task-Task-1", "future_name": "Custom-task-Task-1: name: 3"}}}
{"datetime": "2025-07-30 06:45:14 949353 PM", "level": "INFO", "func_name": "__wakeup", "lineno": 382, "filename": "tasks.py", "msg": {"msg": "__wakeup after future.result()", "vars": {"task_name": "Custom-task-Task-1", "future_name": "Custom-task-Task-1: name: 3", "future._state": "FINISHED"}}}
{"datetime": "2025-07-30 06:45:14 949353 PM", "level": "INFO", "func_name": "__wakeup", "lineno": 398, "filename": "tasks.py", "msg": {"msg": "__wakeup faced no exception when it called future.result()(Custom-task-Task-1: name: 3). calling again __step with no exc. I guess StopIteration will be raised", "vars": {"task_name": "Custom-task-Task-1", "future_name": "Custom-task-Task-1: name: 3"}}}
{"datetime": "2025-07-30 06:45:14 949353 PM", "level": "INFO", "func_name": "__step", "lineno": 231, "filename": "tasks.py", "msg": {"msg": "Entered self.__step", "method_signature": "__step(self, exc = None)", "vars": {"task_name": "Custom-task-Task-1", "exc": "None", "sent_from": "'_wakeup._else'"}}}
{"datetime": "2025-07-30 06:45:14 949353 PM", "level": "INFO", "func_name": "__step", "lineno": 241, "filename": "tasks.py", "msg": {"msg": "will initalized self._fut_waiter value", "vars": {"task_name": "Custom-task-Task-1"}}}
{"datetime": "2025-07-30 06:45:14 949353 PM", "level": "INFO", "func_name": "__step", "lineno": 243, "filename": "tasks.py", "msg": {"msg": "initalized self._fut_waiter to None", "vars": {"task_name": "Custom-task-Task-1"}}}
{"datetime": "2025-07-30 06:45:14 949353 PM", "level": "INFO", "func_name": "__step", "lineno": 248, "filename": "tasks.py", "msg": {"msg": "`try` of try-finally in `self.__step`. Call to __step_run_and_handle_request in next line.", "vars": {"task_name": "Custom-task-Task-1"}}}
{"datetime": "2025-07-30 06:45:14 949353 PM", "level": "INFO", "func_name": "__step_run_and_handle_result", "lineno": 262, "filename": "tasks.py", "msg": {"msg": "__step_run_and_handle_request entered", "method_signature": "__step_run_and_handle_result(self, exc)", "vars": {"task_name": "Custom-task-Task-1", "exc": "None"}}}
{"datetime": "2025-07-30 06:45:14 949353 PM", "level": "INFO", "func_name": "__step_run_and_handle_result", "lineno": 269, "filename": "tasks.py", "msg": {"msg": "`__step_run_and_hanle_result` main try-except exc is None so `coro.send()` in next line.", "vars": {"task_name": "Custom-task-Task-1"}}}
{"datetime": "2025-07-30 06:45:14 949353 PM", "level": "INFO", "func_name": "first", "lineno": 17, "filename": "understanding_tasks.py", "msg": "========== END ==========="}
{"datetime": "2025-07-30 06:45:14 949353 PM", "level": "INFO", "func_name": "__step_run_and_handle_result", "lineno": 282, "filename": "tasks.py", "msg": {"msg": "StopIteration exception encountered.", "vars": {"task_name": "Custom-task-Task-1", "future_name": "NO_AWAITABLE"}}}
{"datetime": "2025-07-30 06:45:14 949353 PM", "level": "INFO", "func_name": "__step_run_and_handle_result", "lineno": 291, "filename": "tasks.py", "msg": {"msg": "__step_run_and_handle_result StopIteration encountered but the task is not cancelled.", "vars": {"task_name": "Custom-task-Task-1", "exc.value": "None"}}}
{"datetime": "2025-07-30 06:45:14 949353 PM", "level": "INFO", "func_name": "__step_run_and_handle_result", "lineno": 294, "filename": "tasks.py", "msg": {"msg": "super().set_result(exc.value)", "vars": {"task_name": "Custom-task-Task-1"}}}
{"datetime": "2025-07-30 06:45:14 956705 PM", "level": "INFO", "func_name": "__step_run_and_handle_result", "lineno": 372, "filename": "tasks.py", "msg": {"msg": "self finally set to None", "vars": {"task_name": "Custom-task-Task-1"}}}
{"datetime": "2025-07-30 06:45:14 957107 PM", "level": "INFO", "func_name": "__step", "lineno": 250, "filename": "tasks.py", "msg": {"msg": "`try` of try-finally in `self.__step`. After __step_run_and_handle_result", "vars": {"task_name": "Custom-task-Task-1"}}}
{"datetime": "2025-07-30 06:45:14 957107 PM", "level": "INFO", "func_name": "__step", "lineno": 255, "filename": "tasks.py", "msg": {"msg": "`finally` of try-finally in `self.__step`. Call to _leave_task next and then set self to None", "vars": {"task_name": "Custom-task-Task-1"}}}
{"datetime": "2025-07-30 06:45:14 957107 PM", "level": "INFO", "func_name": "__step", "lineno": 259, "filename": "tasks.py", "msg": {"msg": "`finally` of try-finally in `self.__step`.Custom-task-Task-1 set to none", "vars": {"task_name": "Custom-task-Task-1"}}}
{"datetime": "2025-07-30 06:45:14 957107 PM", "level": "INFO", "func_name": "__wakeup", "lineno": 401, "filename": "tasks.py", "msg": {"msg": "end of __wakeup. set self = None", "vars": {"task_name": "Custom-task-Task-1", "future_name": "Custom-task-Task-1: name: 3"}}}
{"datetime": "2025-07-30 06:45:14 959508 PM", "level": "INFO", "func_name": "task_factory", "lineno": 407, "filename": "tasks.py", "msg": {"msg": "initalizing task", "vars": {"loop": "<ProactorEventLoop running=False closed=False debug=True>", "coro": "<coroutine object BaseEventLoop.shutdown_asyncgens at 0x00000198acbf4040>", "task_name": null}}}
{"datetime": "2025-07-30 06:45:14 959508 PM", "level": "INFO", "func_name": "__init__", "lineno": 48, "filename": "tasks.py", "msg": {"msg": "__init__ initalized"}}
{"datetime": "2025-07-30 06:45:14 960422 PM", "level": "INFO", "func_name": "__init__", "lineno": 76, "filename": "tasks.py", "msg": {"msg": "self.__step scheduled on EVENT_LOOP in __init__", "vars": {"task_name": "Custom-task-Task-4"}}}
{"datetime": "2025-07-30 06:45:14 960998 PM", "level": "INFO", "func_name": "__init__", "lineno": 78, "filename": "tasks.py", "msg": {"msg": "__init__ after scheduling __step on EVENT_LOOP using loop.call_soon", "vars": {"task_name": "Custom-task-Task-4"}}}
{"datetime": "2025-07-30 06:45:14 961513 PM", "level": "INFO", "func_name": "__step", "lineno": 231, "filename": "tasks.py", "msg": {"msg": "Entered self.__step", "method_signature": "__step(self, exc = None)", "vars": {"task_name": "Custom-task-Task-4", "exc": "None", "sent_from": "'__init__'"}}}
{"datetime": "2025-07-30 06:45:14 961513 PM", "level": "INFO", "func_name": "__step", "lineno": 241, "filename": "tasks.py", "msg": {"msg": "will initalized self._fut_waiter value", "vars": {"task_name": "Custom-task-Task-4"}}}
{"datetime": "2025-07-30 06:45:14 961513 PM", "level": "INFO", "func_name": "__step", "lineno": 243, "filename": "tasks.py", "msg": {"msg": "initalized self._fut_waiter to None", "vars": {"task_name": "Custom-task-Task-4"}}}
{"datetime": "2025-07-30 06:45:14 962521 PM", "level": "INFO", "func_name": "__step", "lineno": 248, "filename": "tasks.py", "msg": {"msg": "`try` of try-finally in `self.__step`. Call to __step_run_and_handle_request in next line.", "vars": {"task_name": "Custom-task-Task-4"}}}
{"datetime": "2025-07-30 06:45:14 962521 PM", "level": "INFO", "func_name": "__step_run_and_handle_result", "lineno": 262, "filename": "tasks.py", "msg": {"msg": "__step_run_and_handle_request entered", "method_signature": "__step_run_and_handle_result(self, exc)", "vars": {"task_name": "Custom-task-Task-4", "exc": "None"}}}
{"datetime": "2025-07-30 06:45:14 962521 PM", "level": "INFO", "func_name": "__step_run_and_handle_result", "lineno": 269, "filename": "tasks.py", "msg": {"msg": "`__step_run_and_hanle_result` main try-except exc is None so `coro.send()` in next line.", "vars": {"task_name": "Custom-task-Task-4"}}}
{"datetime": "2025-07-30 06:45:14 962521 PM", "level": "INFO", "func_name": "__step_run_and_handle_result", "lineno": 282, "filename": "tasks.py", "msg": {"msg": "StopIteration exception encountered.", "vars": {"task_name": "Custom-task-Task-4", "future_name": "NO_AWAITABLE"}}}
{"datetime": "2025-07-30 06:45:14 963521 PM", "level": "INFO", "func_name": "__step_run_and_handle_result", "lineno": 291, "filename": "tasks.py", "msg": {"msg": "__step_run_and_handle_result StopIteration encountered but the task is not cancelled.", "vars": {"task_name": "Custom-task-Task-4", "exc.value": "None"}}}
{"datetime": "2025-07-30 06:45:14 963833 PM", "level": "INFO", "func_name": "__step_run_and_handle_result", "lineno": 294, "filename": "tasks.py", "msg": {"msg": "super().set_result(exc.value)", "vars": {"task_name": "Custom-task-Task-4"}}}
{"datetime": "2025-07-30 06:45:14 963833 PM", "level": "INFO", "func_name": "__step_run_and_handle_result", "lineno": 372, "filename": "tasks.py", "msg": {"msg": "self finally set to None", "vars": {"task_name": "Custom-task-Task-4"}}}
{"datetime": "2025-07-30 06:45:14 963833 PM", "level": "INFO", "func_name": "__step", "lineno": 250, "filename": "tasks.py", "msg": {"msg": "`try` of try-finally in `self.__step`. After __step_run_and_handle_result", "vars": {"task_name": "Custom-task-Task-4"}}}
{"datetime": "2025-07-30 06:45:14 963833 PM", "level": "INFO", "func_name": "__step", "lineno": 255, "filename": "tasks.py", "msg": {"msg": "`finally` of try-finally in `self.__step`. Call to _leave_task next and then set self to None", "vars": {"task_name": "Custom-task-Task-4"}}}
{"datetime": "2025-07-30 06:45:14 963833 PM", "level": "INFO", "func_name": "__step", "lineno": 259, "filename": "tasks.py", "msg": {"msg": "`finally` of try-finally in `self.__step`.Custom-task-Task-4 set to none", "vars": {"task_name": "Custom-task-Task-4"}}}
{"datetime": "2025-07-30 06:45:14 968175 PM", "level": "INFO", "func_name": "task_factory", "lineno": 407, "filename": "tasks.py", "msg": {"msg": "initalizing task", "vars": {"loop": "<ProactorEventLoop running=False closed=False debug=True>", "coro": "<coroutine object BaseEventLoop.shutdown_default_executor at 0x00000198acb5e840>", "task_name": null}}}
{"datetime": "2025-07-30 06:45:14 968175 PM", "level": "INFO", "func_name": "__init__", "lineno": 48, "filename": "tasks.py", "msg": {"msg": "__init__ initalized"}}
{"datetime": "2025-07-30 06:45:14 969306 PM", "level": "INFO", "func_name": "__init__", "lineno": 76, "filename": "tasks.py", "msg": {"msg": "self.__step scheduled on EVENT_LOOP in __init__", "vars": {"task_name": "Custom-task-Task-5"}}}
{"datetime": "2025-07-30 06:45:14 969306 PM", "level": "INFO", "func_name": "__init__", "lineno": 78, "filename": "tasks.py", "msg": {"msg": "__init__ after scheduling __step on EVENT_LOOP using loop.call_soon", "vars": {"task_name": "Custom-task-Task-5"}}}
{"datetime": "2025-07-30 06:45:14 970303 PM", "level": "INFO", "func_name": "__step", "lineno": 231, "filename": "tasks.py", "msg": {"msg": "Entered self.__step", "method_signature": "__step(self, exc = None)", "vars": {"task_name": "Custom-task-Task-5", "exc": "None", "sent_from": "'__init__'"}}}
{"datetime": "2025-07-30 06:45:14 970303 PM", "level": "INFO", "func_name": "__step", "lineno": 241, "filename": "tasks.py", "msg": {"msg": "will initalized self._fut_waiter value", "vars": {"task_name": "Custom-task-Task-5"}}}
{"datetime": "2025-07-30 06:45:14 970964 PM", "level": "INFO", "func_name": "__step", "lineno": 243, "filename": "tasks.py", "msg": {"msg": "initalized self._fut_waiter to None", "vars": {"task_name": "Custom-task-Task-5"}}}
{"datetime": "2025-07-30 06:45:14 970964 PM", "level": "INFO", "func_name": "__step", "lineno": 248, "filename": "tasks.py", "msg": {"msg": "`try` of try-finally in `self.__step`. Call to __step_run_and_handle_request in next line.", "vars": {"task_name": "Custom-task-Task-5"}}}
{"datetime": "2025-07-30 06:45:14 971434 PM", "level": "INFO", "func_name": "__step_run_and_handle_result", "lineno": 262, "filename": "tasks.py", "msg": {"msg": "__step_run_and_handle_request entered", "method_signature": "__step_run_and_handle_result(self, exc)", "vars": {"task_name": "Custom-task-Task-5", "exc": "None"}}}
{"datetime": "2025-07-30 06:45:14 971434 PM", "level": "INFO", "func_name": "__step_run_and_handle_result", "lineno": 269, "filename": "tasks.py", "msg": {"msg": "`__step_run_and_hanle_result` main try-except exc is None so `coro.send()` in next line.", "vars": {"task_name": "Custom-task-Task-5"}}}
{"datetime": "2025-07-30 06:45:14 971434 PM", "level": "INFO", "func_name": "__step_run_and_handle_result", "lineno": 282, "filename": "tasks.py", "msg": {"msg": "StopIteration exception encountered.", "vars": {"task_name": "Custom-task-Task-5", "future_name": "NO_AWAITABLE"}}}
{"datetime": "2025-07-30 06:45:14 971434 PM", "level": "INFO", "func_name": "__step_run_and_handle_result", "lineno": 291, "filename": "tasks.py", "msg": {"msg": "__step_run_and_handle_result StopIteration encountered but the task is not cancelled.", "vars": {"task_name": "Custom-task-Task-5", "exc.value": "None"}}}
{"datetime": "2025-07-30 06:45:14 972440 PM", "level": "INFO", "func_name": "__step_run_and_handle_result", "lineno": 294, "filename": "tasks.py", "msg": {"msg": "super().set_result(exc.value)", "vars": {"task_name": "Custom-task-Task-5"}}}
{"datetime": "2025-07-30 06:45:14 972440 PM", "level": "INFO", "func_name": "__step_run_and_handle_result", "lineno": 372, "filename": "tasks.py", "msg": {"msg": "self finally set to None", "vars": {"task_name": "Custom-task-Task-5"}}}
{"datetime": "2025-07-30 06:45:14 972440 PM", "level": "INFO", "func_name": "__step", "lineno": 250, "filename": "tasks.py", "msg": {"msg": "`try` of try-finally in `self.__step`. After __step_run_and_handle_result", "vars": {"task_name": "Custom-task-Task-5"}}}
{"datetime": "2025-07-30 06:45:14 972440 PM", "level": "INFO", "func_name": "__step", "lineno": 255, "filename": "tasks.py", "msg": {"msg": "`finally` of try-finally in `self.__step`. Call to _leave_task next and then set self to None", "vars": {"task_name": "Custom-task-Task-5"}}}
{"datetime": "2025-07-30 06:45:14 972440 PM", "level": "INFO", "func_name": "__step", "lineno": 259, "filename": "tasks.py", "msg": {"msg": "`finally` of try-finally in `self.__step`.Custom-task-Task-5 set to none", "vars": {"task_name": "Custom-task-Task-5"}}}
