{"datetime": "2025-07-30 06:44:15 626427 PM", "level": "INFO", "func_name": "main", "lineno": 40, "filename": "understanding_tasks.py", "msg": "Main function calling"}
{"datetime": "2025-07-30 06:44:15 626427 PM", "level": "INFO", "func_name": "task_factory", "lineno": 407, "filename": "tasks.py", "msg": {"msg": "initalizing task", "vars": {"loop": "<ProactorEventLoop running=True closed=False debug=True>", "coro": "<coroutine object noawait at 0x000002922222c040>", "task_name": null}}}
{"datetime": "2025-07-30 06:44:15 626427 PM", "level": "INFO", "func_name": "__init__", "lineno": 48, "filename": "tasks.py", "msg": {"msg": "__init__ initalized"}}
{"datetime": "2025-07-30 06:44:15 626427 PM", "level": "INFO", "func_name": "__init__", "lineno": 76, "filename": "tasks.py", "msg": {"msg": "self.__step scheduled on EVENT_LOOP in __init__", "vars": {"task_name": "Custom-task-Task-1"}}}
{"datetime": "2025-07-30 06:44:15 648472 PM", "level": "INFO", "func_name": "__init__", "lineno": 78, "filename": "tasks.py", "msg": {"msg": "__init__ after scheduling __step on EVENT_LOOP using loop.call_soon", "vars": {"task_name": "Custom-task-Task-1"}}}
{"datetime": "2025-07-30 06:44:15 648472 PM", "level": "INFO", "func_name": "__step", "lineno": 231, "filename": "tasks.py", "msg": {"msg": "Entered self.__step", "method_signature": "__step(self, exc = None)", "vars": {"task_name": "Custom-task-Task-1", "exc": "None", "sent_from": "'__init__'"}}}
{"datetime": "2025-07-30 06:44:15 648472 PM", "level": "INFO", "func_name": "__step", "lineno": 241, "filename": "tasks.py", "msg": {"msg": "will initalized self._fut_waiter value", "vars": {"task_name": "Custom-task-Task-1"}}}
{"datetime": "2025-07-30 06:44:15 648472 PM", "level": "INFO", "func_name": "__step", "lineno": 243, "filename": "tasks.py", "msg": {"msg": "initalized self._fut_waiter to None", "vars": {"task_name": "Custom-task-Task-1"}}}
{"datetime": "2025-07-30 06:44:15 648472 PM", "level": "INFO", "func_name": "__step", "lineno": 248, "filename": "tasks.py", "msg": {"msg": "`try` of try-finally in `self.__step`. Call to __step_run_and_handle_request in next line.", "vars": {"task_name": "Custom-task-Task-1"}}}
{"datetime": "2025-07-30 06:44:15 658444 PM", "level": "INFO", "func_name": "__step_run_and_handle_result", "lineno": 262, "filename": "tasks.py", "msg": {"msg": "__step_run_and_handle_request entered", "method_signature": "__step_run_and_handle_result(self, exc)", "vars": {"task_name": "Custom-task-Task-1", "exc": "None"}}}
{"datetime": "2025-07-30 06:44:15 658444 PM", "level": "INFO", "func_name": "__step_run_and_handle_result", "lineno": 269, "filename": "tasks.py", "msg": {"msg": "`__step_run_and_hanle_result` main try-except exc is None so `coro.send()` in next line.", "vars": {"task_name": "Custom-task-Task-1"}}}
{"datetime": "2025-07-30 06:44:15 659374 PM", "level": "INFO", "func_name": "noawait", "lineno": 38, "filename": "understanding_tasks.py", "msg": "================== no awaits ============="}
{"datetime": "2025-07-30 06:44:15 659374 PM", "level": "INFO", "func_name": "__step_run_and_handle_result", "lineno": 282, "filename": "tasks.py", "msg": {"msg": "StopIteration exception encountered.", "vars": {"task_name": "Custom-task-Task-1", "future_name": "NO_AWAITABLE"}}}
{"datetime": "2025-07-30 06:44:15 660126 PM", "level": "INFO", "func_name": "__step_run_and_handle_result", "lineno": 291, "filename": "tasks.py", "msg": {"msg": "__step_run_and_handle_result StopIteration encountered but the task is not cancelled.", "vars": {"task_name": "Custom-task-Task-1", "exc.value": "None"}}}
{"datetime": "2025-07-30 06:44:15 661133 PM", "level": "INFO", "func_name": "__step_run_and_handle_result", "lineno": 294, "filename": "tasks.py", "msg": {"msg": "super().set_result(exc.value)", "vars": {"task_name": "Custom-task-Task-1"}}}
{"datetime": "2025-07-30 06:44:15 661133 PM", "level": "INFO", "func_name": "__step_run_and_handle_result", "lineno": 372, "filename": "tasks.py", "msg": {"msg": "self finally set to None", "vars": {"task_name": "Custom-task-Task-1"}}}
{"datetime": "2025-07-30 06:44:15 661133 PM", "level": "INFO", "func_name": "__step", "lineno": 250, "filename": "tasks.py", "msg": {"msg": "`try` of try-finally in `self.__step`. After __step_run_and_handle_result", "vars": {"task_name": "Custom-task-Task-1"}}}
{"datetime": "2025-07-30 06:44:15 662133 PM", "level": "INFO", "func_name": "__step", "lineno": 255, "filename": "tasks.py", "msg": {"msg": "`finally` of try-finally in `self.__step`. Call to _leave_task next and then set self to None", "vars": {"task_name": "Custom-task-Task-1"}}}
{"datetime": "2025-07-30 06:44:15 662702 PM", "level": "INFO", "func_name": "__step", "lineno": 259, "filename": "tasks.py", "msg": {"msg": "`finally` of try-finally in `self.__step`.Custom-task-Task-1 set to none", "vars": {"task_name": "Custom-task-Task-1"}}}
{"datetime": "2025-07-30 06:44:15 662702 PM", "level": "INFO", "func_name": "task_factory", "lineno": 407, "filename": "tasks.py", "msg": {"msg": "initalizing task", "vars": {"loop": "<ProactorEventLoop running=False closed=False debug=True>", "coro": "<coroutine object BaseEventLoop.shutdown_asyncgens at 0x0000029222274040>", "task_name": null}}}
{"datetime": "2025-07-30 06:44:15 664453 PM", "level": "INFO", "func_name": "__init__", "lineno": 48, "filename": "tasks.py", "msg": {"msg": "__init__ initalized"}}
{"datetime": "2025-07-30 06:44:15 665459 PM", "level": "INFO", "func_name": "__init__", "lineno": 76, "filename": "tasks.py", "msg": {"msg": "self.__step scheduled on EVENT_LOOP in __init__", "vars": {"task_name": "Custom-task-Task-2"}}}
{"datetime": "2025-07-30 06:44:15 665459 PM", "level": "INFO", "func_name": "__init__", "lineno": 78, "filename": "tasks.py", "msg": {"msg": "__init__ after scheduling __step on EVENT_LOOP using loop.call_soon", "vars": {"task_name": "Custom-task-Task-2"}}}
{"datetime": "2025-07-30 06:44:15 666559 PM", "level": "INFO", "func_name": "__step", "lineno": 231, "filename": "tasks.py", "msg": {"msg": "Entered self.__step", "method_signature": "__step(self, exc = None)", "vars": {"task_name": "Custom-task-Task-2", "exc": "None", "sent_from": "'__init__'"}}}
{"datetime": "2025-07-30 06:44:15 667464 PM", "level": "INFO", "func_name": "__step", "lineno": 241, "filename": "tasks.py", "msg": {"msg": "will initalized self._fut_waiter value", "vars": {"task_name": "Custom-task-Task-2"}}}
{"datetime": "2025-07-30 06:44:15 667464 PM", "level": "INFO", "func_name": "__step", "lineno": 243, "filename": "tasks.py", "msg": {"msg": "initalized self._fut_waiter to None", "vars": {"task_name": "Custom-task-Task-2"}}}
{"datetime": "2025-07-30 06:44:15 667464 PM", "level": "INFO", "func_name": "__step", "lineno": 248, "filename": "tasks.py", "msg": {"msg": "`try` of try-finally in `self.__step`. Call to __step_run_and_handle_request in next line.", "vars": {"task_name": "Custom-task-Task-2"}}}
{"datetime": "2025-07-30 06:44:15 668463 PM", "level": "INFO", "func_name": "__step_run_and_handle_result", "lineno": 262, "filename": "tasks.py", "msg": {"msg": "__step_run_and_handle_request entered", "method_signature": "__step_run_and_handle_result(self, exc)", "vars": {"task_name": "Custom-task-Task-2", "exc": "None"}}}
{"datetime": "2025-07-30 06:44:15 668463 PM", "level": "INFO", "func_name": "__step_run_and_handle_result", "lineno": 269, "filename": "tasks.py", "msg": {"msg": "`__step_run_and_hanle_result` main try-except exc is None so `coro.send()` in next line.", "vars": {"task_name": "Custom-task-Task-2"}}}
{"datetime": "2025-07-30 06:44:15 668463 PM", "level": "INFO", "func_name": "__step_run_and_handle_result", "lineno": 282, "filename": "tasks.py", "msg": {"msg": "StopIteration exception encountered.", "vars": {"task_name": "Custom-task-Task-2", "future_name": "NO_AWAITABLE"}}}
{"datetime": "2025-07-30 06:44:15 668463 PM", "level": "INFO", "func_name": "__step_run_and_handle_result", "lineno": 291, "filename": "tasks.py", "msg": {"msg": "__step_run_and_handle_result StopIteration encountered but the task is not cancelled.", "vars": {"task_name": "Custom-task-Task-2", "exc.value": "None"}}}
{"datetime": "2025-07-30 06:44:15 670311 PM", "level": "INFO", "func_name": "__step_run_and_handle_result", "lineno": 294, "filename": "tasks.py", "msg": {"msg": "super().set_result(exc.value)", "vars": {"task_name": "Custom-task-Task-2"}}}
{"datetime": "2025-07-30 06:44:15 670311 PM", "level": "INFO", "func_name": "__step_run_and_handle_result", "lineno": 372, "filename": "tasks.py", "msg": {"msg": "self finally set to None", "vars": {"task_name": "Custom-task-Task-2"}}}
{"datetime": "2025-07-30 06:44:15 670311 PM", "level": "INFO", "func_name": "__step", "lineno": 250, "filename": "tasks.py", "msg": {"msg": "`try` of try-finally in `self.__step`. After __step_run_and_handle_result", "vars": {"task_name": "Custom-task-Task-2"}}}
{"datetime": "2025-07-30 06:44:15 671324 PM", "level": "INFO", "func_name": "__step", "lineno": 255, "filename": "tasks.py", "msg": {"msg": "`finally` of try-finally in `self.__step`. Call to _leave_task next and then set self to None", "vars": {"task_name": "Custom-task-Task-2"}}}
{"datetime": "2025-07-30 06:44:15 671324 PM", "level": "INFO", "func_name": "__step", "lineno": 259, "filename": "tasks.py", "msg": {"msg": "`finally` of try-finally in `self.__step`.Custom-task-Task-2 set to none", "vars": {"task_name": "Custom-task-Task-2"}}}
{"datetime": "2025-07-30 06:44:15 674026 PM", "level": "INFO", "func_name": "task_factory", "lineno": 407, "filename": "tasks.py", "msg": {"msg": "initalizing task", "vars": {"loop": "<ProactorEventLoop running=False closed=False debug=True>", "coro": "<coroutine object BaseEventLoop.shutdown_default_executor at 0x00000292221da840>", "task_name": null}}}
{"datetime": "2025-07-30 06:44:15 674026 PM", "level": "INFO", "func_name": "__init__", "lineno": 48, "filename": "tasks.py", "msg": {"msg": "__init__ initalized"}}
{"datetime": "2025-07-30 06:44:15 675032 PM", "level": "INFO", "func_name": "__init__", "lineno": 76, "filename": "tasks.py", "msg": {"msg": "self.__step scheduled on EVENT_LOOP in __init__", "vars": {"task_name": "Custom-task-Task-3"}}}
{"datetime": "2025-07-30 06:44:15 675032 PM", "level": "INFO", "func_name": "__init__", "lineno": 78, "filename": "tasks.py", "msg": {"msg": "__init__ after scheduling __step on EVENT_LOOP using loop.call_soon", "vars": {"task_name": "Custom-task-Task-3"}}}
{"datetime": "2025-07-30 06:44:15 676030 PM", "level": "INFO", "func_name": "__step", "lineno": 231, "filename": "tasks.py", "msg": {"msg": "Entered self.__step", "method_signature": "__step(self, exc = None)", "vars": {"task_name": "Custom-task-Task-3", "exc": "None", "sent_from": "'__init__'"}}}
{"datetime": "2025-07-30 06:44:15 676030 PM", "level": "INFO", "func_name": "__step", "lineno": 241, "filename": "tasks.py", "msg": {"msg": "will initalized self._fut_waiter value", "vars": {"task_name": "Custom-task-Task-3"}}}
{"datetime": "2025-07-30 06:44:15 676030 PM", "level": "INFO", "func_name": "__step", "lineno": 243, "filename": "tasks.py", "msg": {"msg": "initalized self._fut_waiter to None", "vars": {"task_name": "Custom-task-Task-3"}}}
{"datetime": "2025-07-30 06:44:15 676030 PM", "level": "INFO", "func_name": "__step", "lineno": 248, "filename": "tasks.py", "msg": {"msg": "`try` of try-finally in `self.__step`. Call to __step_run_and_handle_request in next line.", "vars": {"task_name": "Custom-task-Task-3"}}}
{"datetime": "2025-07-30 06:44:15 676030 PM", "level": "INFO", "func_name": "__step_run_and_handle_result", "lineno": 262, "filename": "tasks.py", "msg": {"msg": "__step_run_and_handle_request entered", "method_signature": "__step_run_and_handle_result(self, exc)", "vars": {"task_name": "Custom-task-Task-3", "exc": "None"}}}
{"datetime": "2025-07-30 06:44:15 676030 PM", "level": "INFO", "func_name": "__step_run_and_handle_result", "lineno": 269, "filename": "tasks.py", "msg": {"msg": "`__step_run_and_hanle_result` main try-except exc is None so `coro.send()` in next line.", "vars": {"task_name": "Custom-task-Task-3"}}}
{"datetime": "2025-07-30 06:44:15 676030 PM", "level": "INFO", "func_name": "__step_run_and_handle_result", "lineno": 282, "filename": "tasks.py", "msg": {"msg": "StopIteration exception encountered.", "vars": {"task_name": "Custom-task-Task-3", "future_name": "NO_AWAITABLE"}}}
{"datetime": "2025-07-30 06:44:15 676030 PM", "level": "INFO", "func_name": "__step_run_and_handle_result", "lineno": 291, "filename": "tasks.py", "msg": {"msg": "__step_run_and_handle_result StopIteration encountered but the task is not cancelled.", "vars": {"task_name": "Custom-task-Task-3", "exc.value": "None"}}}
{"datetime": "2025-07-30 06:44:15 676030 PM", "level": "INFO", "func_name": "__step_run_and_handle_result", "lineno": 294, "filename": "tasks.py", "msg": {"msg": "super().set_result(exc.value)", "vars": {"task_name": "Custom-task-Task-3"}}}
{"datetime": "2025-07-30 06:44:15 679181 PM", "level": "INFO", "func_name": "__step_run_and_handle_result", "lineno": 372, "filename": "tasks.py", "msg": {"msg": "self finally set to None", "vars": {"task_name": "Custom-task-Task-3"}}}
{"datetime": "2025-07-30 06:44:15 679181 PM", "level": "INFO", "func_name": "__step", "lineno": 250, "filename": "tasks.py", "msg": {"msg": "`try` of try-finally in `self.__step`. After __step_run_and_handle_result", "vars": {"task_name": "Custom-task-Task-3"}}}
{"datetime": "2025-07-30 06:44:15 679181 PM", "level": "INFO", "func_name": "__step", "lineno": 255, "filename": "tasks.py", "msg": {"msg": "`finally` of try-finally in `self.__step`. Call to _leave_task next and then set self to None", "vars": {"task_name": "Custom-task-Task-3"}}}
{"datetime": "2025-07-30 06:44:15 679181 PM", "level": "INFO", "func_name": "__step", "lineno": 259, "filename": "tasks.py", "msg": {"msg": "`finally` of try-finally in `self.__step`.Custom-task-Task-3 set to none", "vars": {"task_name": "Custom-task-Task-3"}}}
